Workbook

Sheet V2_OVERVIEW
A1: V2 — UDP Mapping Report
A2: SAP PowerDesigner Extended Attributes Text mapped to erwin UDPs, and the enrichment of erwin V1 into erwin V2.
A4: Measure | B4: Value | C4: Where it comes from
A5: Model | B5: 02_logistics_segment
A6: Model type | B6: CDM
A7: SAP PD file | B7: 02_logistics_segment.cdm
A9: MAPPING — SAP PD Extended Attributes Text to erwin UDPs
A10: UDP definitions mapped | B10: 13 | C10: udp_schema.json — the erwin UDP dictionary the tool builds
A11: Property values mapped | B11: 1177 | C11: property_manifest.json — one row per value per object
A12: Mapping artefacts | B12: data\udp\02_logistics_segment | C12: Per-model working directory
A14: ENRICHMENT — erwin V1 to erwin V2
A15: UDPs injected into erwin | B15: No
A16: Enrichment stage | B16: COMPARED | C16: SKIPPED / EXTRACTED / INJECTED / COMPARED / FAILED
A17: erwin model read back | B17: 02_logistics_segment.erwin | C17: The .erwin binary the comparison was taken from
A18: Read-back method | B18: binary | C18: com = erwin SCAPI; binary = independent file decode
A19: Read-back reliable | B19: Yes | C19: The binary decoder scores itself and refuses to report below 80%
A21: VERIFICATION — what erwin actually holds
A22: UDP values compared | B22: 1177
A23: UDP mapping pass rate % | B23: 100 | C23: Share of SAP values present and equal in the enriched erwin model
A24: Verdict | B24: PASS
A25: PASS | B25: 1177
A27: V2 FIDELITY (after preprocessing, before enrichment is scored)
A28: V2 fidelity % | B28: 71.12 | C28: SAP PD vs the preprocessed erwin XML
A29: Structural fidelity % | B29: 92.24
A30: Documentation fidelity % | B30: 100 | C30: Comments / Descriptions / Annotations that survived
A31: UDP fidelity % (erwin XML) | B31: 0 | C31: The XML export carries no UDPs — the enriched binary is the evidence above
A33: Notes | B33: Mapped 13 UDP definition(s) and 1177 property value(s). | pywin32 / erwin COM not available on this host; injection skipped. The comparison phase still reads the model back off disk. | 02_logistics_segment: 1177/1177 UDP values match erwin (100.00%), 0 mismatched, 0 missing in erwin.

Sheet UDP_MAPPING_SUMMARY
A1: UDP Migration Report - SAP PowerDesigner to erwin Data Modeler
A3: Run Information
A4: Report generated | B4: 2026-09-04 19:47:04
A5: Model name | B5: 02_logistics_segment
A6: Source SAP model | B6: C:\Users\Shivansh\Downloads\migration-platform_4_sept_final\sappdmodels\cdm\02_logistics_segment.cdm | C6: PowerDesigner model read for this run.
A7: Target erwin model | B7: app\udp_tool\output_erwin_models\02_logistics_segment.erwin | C7: File the UDPs were written into.
A8: PowerDesigner version | B8: 16.7.6.7257
A9: Repository extraction id | B9: 9649844 | C9: Proves which point-in-time extract this migration came from.
A10: Injection executed | B10: No - report built from source data only | C10: Values below are reported as Not Verified because no injection result file was available.
A11: erwin session | B11: Not recorded
A13: Source Model (SAP PowerDesigner)
A14: Complexity band | B14: B4 - High / Very High | C14: From sow_classify.py, per the SOW Complexity Classification Spectrum.
A15: SOW automation range | B15: 20% to 50%
A16: Entities in source model | B16: 195
A17: Attributes in source model | B17: 8
A18: Extension properties found | B18: 10
A19: Extension values found | B19: 650
A21: UDP Definitions
A22: UDP definitions requested | B22: =MAX(0,COUNTA(UDP_DEFINITIONS!$A:$A)-1) | C22: Each UDP is defined twice in erwin, once for the Entity owner and once for the Model owner.
A23: Created in erwin dictionary | B23: =COUNTIF(UDP_DEFINITIONS!$J:$J,"Created*") | C23: Counted per UDP, not per owner.
A24: Updated in erwin dictionary | B24: =COUNTIF(UDP_DEFINITIONS!$J:$J,"Updated*") | C24: UDPs that already existed in the target model and were re-pointed.
A25: Definition failures | B25: =COUNTIF(UDP_DEFINITIONS!$N:$N,"FAILED*") | C25: A UDP counts as failed if erwin rejected either owner definition. See the Exceptions sheet for the reason.
A27: Value Reconciliation
A28: Entities matched in erwin | B28: Not recorded | C28: Entities the injector found in the target .erwin model.
A29: Source values to migrate | B29: =MAX(0,COUNTA(UDP_VALUE_RECON!$C:$C)-1)
A30: Applied to erwin | B30: =COUNTIF(UDP_VALUE_RECON!$H:$H,"Applied*")
A31: Applied and verified (read back) | B31: =COUNTIF(UDP_VALUE_RECON!$I:$I,"Match") | C31: Value was written, then read back out of erwin and compared.
A32: Applied but value altered | B32: =COUNTIF(UDP_VALUE_RECON!$I:$I,"Mismatch")
A33: Not applied | B33: =COUNTIF(UDP_VALUE_RECON!$H:$H,"Skipped*")
A34: Blank source values | B34: =COUNTBLANK(UDP_VALUE_RECON!$E$2:$E$1178) | C34: Properties present in PowerDesigner but holding no value.
A36: Result
A37: Application rate | B37: =IF(B29=0,0,B30/B29) | C37: Share of source values erwin accepted.
A38: Verification rate | B38: =IF(B29=0,0,B31/B29) | C38: Share of source values confirmed identical inside erwin.
A39: High severity exceptions | B39: =COUNTIF(UDP_EXCEPTIONS!$A:$A,"High") | C39: Listed on the Exceptions sheet.
A40: Migration verdict | B40: NOT VERIFIED - NO INJECTION RESULTS | C40: This report was built from source data alone. Re-run batch_run.py to produce a verified report.
A42: Counts on this sheet are live formulas over the other three sheets, so they stay correct if rows are filtered or corrected during review.

Sheet UDP_DEFINITIONS
A1: UDP Name | B1: Inferred Type | C1: Length | D1: Value List (Observed) | E1: Source Path | F1: Source Coverage | G1: Distinct Observed | H1: List Source | I1: erwin Owner Types | J1: erwin Dictionary Action | K1: Values Expected | L1: Values Applied | M1: Values Verified | N1: Definition Status
A2: PD_ObjectID | B2: Text | C2: 40 | I2: Entity, Model | J2: Not Recorded | K2: =COUNTIF(UDP_VALUE_RECON!$C:$C,$A2) | L2: =COUNTIFS(UDP_VALUE_RECON!$C:$C,$A2,UDP_VALUE_RECON!$H:$H,"Applied*") | M2: =COUNTIFS(UDP_VALUE_RECON!$C:$C,$A2,UDP_VALUE_RECON!$I:$I,"Match") | N2: Defined
A3: PD_SourceExtraction | B3: Text | C3: 20 | I3: Entity, Model | J3: Not Recorded | K3: =COUNTIF(UDP_VALUE_RECON!$C:$C,$A3) | L3: =COUNTIFS(UDP_VALUE_RECON!$C:$C,$A3,UDP_VALUE_RECON!$H:$H,"Applied*") | M3: =COUNTIFS(UDP_VALUE_RECON!$C:$C,$A3,UDP_VALUE_RECON!$I:$I,"Match") | N3: Defined
A4: PD_SourceModel | B4: Text | C4: 120 | I4: Entity, Model | J4: Not Recorded | K4: =COUNTIF(UDP_VALUE_RECON!$C:$C,$A4) | L4: =COUNTIFS(UDP_VALUE_RECON!$C:$C,$A4,UDP_VALUE_RECON!$H:$H,"Applied*") | M4: =COUNTIFS(UDP_VALUE_RECON!$C:$C,$A4,UDP_VALUE_RECON!$I:$I,"Match") | N4: Defined
A5: MTED_EDaM_Entity_Data_Category | B5: List | D5: <unspecified> | E5: SHL_CDM_EntityPropertyExtension.MTED_EDaM_Entity_Data_Category | F5: 100% | G5: 1 | H5: OBSERVED - confirm against BIM-core.xem | I5: Entity, Model | J5: Not Recorded | K5: =COUNTIF(UDP_VALUE_RECON!$C:$C,$A5) | L5: =COUNTIFS(UDP_VALUE_RECON!$C:$C,$A5,UDP_VALUE_RECON!$H:$H,"Applied*") | M5: =COUNTIFS(UDP_VALUE_RECON!$C:$C,$A5,UDP_VALUE_RECON!$I:$I,"Match") | N5: Defined as List - observed values only, confirm against BIM-core.xem
A6: MTED_EDaM_Security_Classification | B6: List | D6: <unspecified> | Restricted | E6: SHL_CDM_EntityPropertyExtension.MTED_EDaM_Security_Classification | F6: 100% | G6: 2 | H6: OBSERVED - confirm against BIM-core.xem | I6: Entity, Model | J6: Not Recorded | K6: =COUNTIF(UDP_VALUE_RECON!$C:$C,$A6) | L6: =COUNTIFS(UDP_VALUE_RECON!$C:$C,$A6,UDP_VALUE_RECON!$H:$H,"Applied*") | M6: =COUNTIFS(UDP_VALUE_RECON!$C:$C,$A6,UDP_VALUE_RECON!$I:$I,"Match") | N6: Defined as List - observed values only, confirm against BIM-core.xem
A7: MTED_EDaM_Entity_Maps_To_Entity | B7: Text | C7: 65 | E7: SHL_CDM_EntityPropertyExtension.MTED_EDaM_Entity_Maps_To_Entity | F7: 100% | G7: 17 | I7: Entity, Model | J7: Not Recorded | K7: =COUNTIF(UDP_VALUE_RECON!$C:$C,$A7) | L7: =COUNTIFS(UDP_VALUE_RECON!$C:$C,$A7,UDP_VALUE_RECON!$H:$H,"Applied*") | M7: =COUNTIFS(UDP_VALUE_RECON!$C:$C,$A7,UDP_VALUE_RECON!$I:$I,"Match") | N7: Defined
A8: MTED_EDaM_Design_Status | B8: List | D8: Draft | E8: SHL_CDM_EntityPropertyExtension.MTED_EDaM_Design_Status | F8: 100% | G8: 1 | H8: OBSERVED - confirm against BIM-core.xem | I8: Entity, Model | J8: Not Recorded | K8: =COUNTIF(UDP_VALUE_RECON!$C:$C,$A8) | L8: =COUNTIFS(UDP_VALUE_RECON!$C:$C,$A8,UDP_VALUE_RECON!$H:$H,"Applied*") | M8: =COUNTIFS(UDP_VALUE_RECON!$C:$C,$A8,UDP_VALUE_RECON!$I:$I,"Match") | N8: Defined as List - observed values only, confirm against BIM-core.xem
A9: MTED_EDaM_Data_Owner | B9: List | D9: Chris Ragan | E9: SHL_CDM_EntityPropertyExtension.MTED_EDaM_Data_Owner | F9: 100% | G9: 1 | H9: OBSERVED - confirm against BIM-core.xem | I9: Entity, Model | J9: Not Recorded | K9: =COUNTIF(UDP_VALUE_RECON!$C:$C,$A9) | L9: =COUNTIFS(UDP_VALUE_RECON!$C:$C,$A9,UDP_VALUE_RECON!$H:$H,"Applied*") | M9: =COUNTIFS(UDP_VALUE_RECON!$C:$C,$A9,UDP_VALUE_RECON!$I:$I,"Match") | N9: Defined as List - observed values only, confirm against BIM-core.xem
A10: DataSourcePersist | B10: List | D10: C:\Apps\SA extraction\02_Logistics_Segment.csv | E10: EXCEL_IMPORT.DataSourcePersist | F10: 100% | G10: 1 | H10: OBSERVED - confirm against BIM-core.xem | I10: Entity, Model | J10: Not Recorded | K10: =COUNTIF(UDP_VALUE_RECON!$C:$C,$A10) | L10: =COUNTIFS(UDP_VALUE_RECON!$C:$C,$A10,UDP_VALUE_RECON!$H:$H,"Applied*") | M10: =COUNTIFS(UDP_VALUE_RECON!$C:$C,$A10,UDP_VALUE_RECON!$I:$I,"Match") | N10: Defined - no source values to migrate
A11: ImportedType | B11: List | D11: Entity | E11: EXCEL_IMPORT.ImportedType | F11: 100% | G11: 1 | H11: OBSERVED - confirm against BIM-core.xem | I11: Entity, Model | J11: Not Recorded | K11: =COUNTIF(UDP_VALUE_RECON!$C:$C,$A11) | L11: =COUNTIFS(UDP_VALUE_RECON!$C:$C,$A11,UDP_VALUE_RECON!$H:$H,"Applied*") | M11: =COUNTIFS(UDP_VALUE_RECON!$C:$C,$A11,UDP_VALUE_RECON!$I:$I,"Match") | N11: Defined - no source values to migrate
A12: PersistBooleanMapping | B12: List | D12: true | false | E12: EXCEL_IMPORT.PersistBooleanMapping | F12: 100% | G12: 1 | H12: OBSERVED - confirm against BIM-core.xem | I12: Entity, Model | J12: Not Recorded | K12: =COUNTIF(UDP_VALUE_RECON!$C:$C,$A12) | L12: =COUNTIFS(UDP_VALUE_RECON!$C:$C,$A12,UDP_VALUE_RECON!$H:$H,"Applied*") | M12: =COUNTIFS(UDP_VALUE_RECON!$C:$C,$A12,UDP_VALUE_RECON!$I:$I,"Match") | N12: Defined - no source values to migrate
A13: ColumnKind | B13: List | D13: Standard | E13: EXCEL_IMPORT.ColumnKind | F13: 100% | G13: 1 | H13: OBSERVED - confirm against BIM-core.xem | I13: Entity, Model | J13: Not Recorded | K13: =COUNTIF(UDP_VALUE_RECON!$C:$C,$A13) | L13: =COUNTIFS(UDP_VALUE_RECON!$C:$C,$A13,UDP_VALUE_RECON!$H:$H,"Applied*") | M13: =COUNTIFS(UDP_VALUE_RECON!$C:$C,$A13,UDP_VALUE_RECON!$I:$I,"Match") | N13: Defined - no source values to migrate
A14: Attribute | B14: List | D14: Name | SHL_CDM_EntityPropertyExtension.MTED_EDaM_Data_Owner | SHL_CDM_EntityPropertyExtension.MTED_EDaM_Design_Status | SHL_CDM_EntityPropertyExtension.MTED_EDaM_Entity_Data_Category | SHL_CDM_EntityPropertyExtension.MTED_EDaM_Entity_Maps_To_Entity | SHL_CDM_EntityPropertyExtension.MTED_EDaM_Mapping_Note | SHL_CDM_EntityPropertyExtension.MTED_EDaM_Security_Classification | SHL_CDM_EntityPropertyExtension.MTED_EDaM_Version_Date | SHL_CDM_EntityPropertyExtension.MTED_Version_No | E14: EXCEL_IMPORT.Attribute | F14: 100% | G14: 9 | H14: OBSERVED - confirm against BIM-core.xem | I14: Entity, Model | J14: Not Recorded | K14: =COUNTIF(UDP_VALUE_RECON!$C:$C,$A14) | L14: =COUNTIFS(UDP_VALUE_RECON!$C:$C,$A14,UDP_VALUE_RECON!$H:$H,"Applied*") | M14: =COUNTIFS(UDP_VALUE_RECON!$C:$C,$A14,UDP_VALUE_RECON!$I:$I,"Match") | N14: Defined - no source values to migrate

Sheet UDP_VALUE_RECON
A1: Entity Name | B1: PD Object ID | C1: UDP | D1: Source Path | E1: Source Value (PowerDesigner) | F1: Target Value (erwin) | G1: Applied To | H1: Status | I1: Match | J1: Notes
A2: BUSINESS_AREA | B2: 607112A9-B26C-4450-9B95-AE4ACF176A92 | C2: PD_ObjectID | E2: 607112A9-B26C-4450-9B95-AE4ACF176A92 | G2: Entity | H2: Not Verified - No Injection Result | I2: Not Applied | J2: No injection result recorded for this value.
A3: BUSINESS_AREA | B3: 607112A9-B26C-4450-9B95-AE4ACF176A92 | C3: PD_SourceExtraction | E3: 46603045 | G3: Entity | H3: Not Verified - No Injection Result | I3: Not Applied | J3: No injection result recorded for this value.
A4: BUSINESS_AREA | B4: 607112A9-B26C-4450-9B95-AE4ACF176A92 | C4: PD_SourceModel | E4: 02_logistics_segment | G4: Entity | H4: Not Verified - No Injection Result | I4: Not Applied | J4: No injection result recorded for this value.
A5: BUSINESS_AREA | B5: 607112A9-B26C-4450-9B95-AE4ACF176A92 | C5: MTED_EDaM_Entity_Data_Category | D5: SHL_CDM_EntityPropertyExtension.MTED_EDaM_Entity_Data_Category | E5: <unspecified> | G5: Entity | H5: Not Verified - No Injection Result | I5: Not Applied | J5: No injection result recorded for this value.
A6: BUSINESS_AREA | B6: 607112A9-B26C-4450-9B95-AE4ACF176A92 | C6: MTED_EDaM_Security_Classification | D6: SHL_CDM_EntityPropertyExtension.MTED_EDaM_Security_Classification | E6: <unspecified> | G6: Entity | H6: Not Verified - No Injection Result | I6: Not Applied | J6: No injection result recorded for this value.
A7: BUSINESS_AREA | B7: 607112A9-B26C-4450-9B95-AE4ACF176A92 | C7: MTED_EDaM_Entity_Maps_To_Entity | D7: SHL_CDM_EntityPropertyExtension.MTED_EDaM_Entity_Maps_To_Entity | E7: Site | G7: Entity | H7: Not Verified - No Injection Result | I7: Not Applied | J7: No injection result recorded for this value.
A8: BUSINESS_AREA | B8: 607112A9-B26C-4450-9B95-AE4ACF176A92 | C8: MTED_EDaM_Design_Status | D8: SHL_CDM_EntityPropertyExtension.MTED_EDaM_Design_Status | E8: Draft | G8: Entity | H8: Not Verified - No Injection Result | I8: Not Applied | J8: No injection result recorded for this value.
A9: Site | B9: 70BFCC9F-609E-4A95-BDEA-8EDC38F07CF7 | C9: PD_ObjectID | E9: 70BFCC9F-609E-4A95-BDEA-8EDC38F07CF7 | G9: Entity | H9: Not Verified - No Injection Result | I9: Not Applied | J9: No injection result recorded for this value.
A10: Site | B10: 70BFCC9F-609E-4A95-BDEA-8EDC38F07CF7 | C10: PD_SourceExtraction | E10: 46603045 | G10: Entity | H10: Not Verified - No Injection Result | I10: Not Applied | J10: No injection result recorded for this value.
A11: Site | B11: 70BFCC9F-609E-4A95-BDEA-8EDC38F07CF7 | C11: PD_SourceModel | E11: 02_logistics_segment | G11: Entity | H11: Not Verified - No Injection Result | I11: Not Applied | J11: No injection result recorded for this value.
A12: Site | B12: 70BFCC9F-609E-4A95-BDEA-8EDC38F07CF7 | C12: MTED_EDaM_Entity_Data_Category | D12: SHL_CDM_EntityPropertyExtension.MTED_EDaM_Entity_Data_Category | E12: <unspecified> | G12: Entity | H12: Not Verified - No Injection Result | I12: Not Applied | J12: No injection result recorded for this value.
A13: Site | B13: 70BFCC9F-609E-4A95-BDEA-8EDC38F07CF7 | C13: MTED_EDaM_Security_Classification | D13: SHL_CDM_EntityPropertyExtension.MTED_EDaM_Security_Classification | E13: <unspecified> | G13: Entity | H13: Not Verified - No Injection Result | I13: Not Applied | J13: No injection result recorded for this value.
A14: Site | B14: 70BFCC9F-609E-4A95-BDEA-8EDC38F07CF7 | C14: MTED_EDaM_Design_Status | D14: SHL_CDM_EntityPropertyExtension.MTED_EDaM_Design_Status | E14: Draft | G14: Entity | H14: Not Verified - No Injection Result | I14: Not Applied | J14: No injection result recorded for this value.
A15: BUSINESS_ENTITY | B15: A2ABBA5A-0035-4CE3-AF5C-CDF4CC070A03 | C15: PD_ObjectID | E15: A2ABBA5A-0035-4CE3-AF5C-CDF4CC070A03 | G15: Entity | H15: Not Verified - No Injection Result | I15: Not Applied | J15: No injection result recorded for this value.
A16: BUSINESS_ENTITY | B16: A2ABBA5A-0035-4CE3-AF5C-CDF4CC070A03 | C16: PD_SourceExtraction | E16: 46603045 | G16: Entity | H16: Not Verified - No Injection Result | I16: Not Applied | J16: No injection result recorded for this value.
A17: BUSINESS_ENTITY | B17: A2ABBA5A-0035-4CE3-AF5C-CDF4CC070A03 | C17: PD_SourceModel | E17: 02_logistics_segment | G17: Entity | H17: Not Verified - No Injection Result | I17: Not Applied | J17: No injection result recorded for this value.
A18: BUSINESS_ENTITY | B18: A2ABBA5A-0035-4CE3-AF5C-CDF4CC070A03 | C18: MTED_EDaM_Entity_Data_Category | D18: SHL_CDM_EntityPropertyExtension.MTED_EDaM_Entity_Data_Category | E18: <unspecified> | G18: Entity | H18: Not Verified - No Injection Result | I18: Not Applied | J18: No injection result recorded for this value.
A19: BUSINESS_ENTITY | B19: A2ABBA5A-0035-4CE3-AF5C-CDF4CC070A03 | C19: MTED_EDaM_Security_Classification | D19: SHL_CDM_EntityPropertyExtension.MTED_EDaM_Security_Classification | E19: <unspecified> | G19: Entity | H19: Not Verified - No Injection Result | I19: Not Applied | J19: No injection result recorded for this value.
A20: BUSINESS_ENTITY | B20: A2ABBA5A-0035-4CE3-AF5C-CDF4CC070A03 | C20: MTED_EDaM_Entity_Maps_To_Entity | D20: SHL_CDM_EntityPropertyExtension.MTED_EDaM_Entity_Maps_To_Entity | E20: "HR Organisation" | G20: Entity | H20: Not Verified - No Injection Result | I20: Not Applied | J20: No injection result recorded for this value.
A21: BUSINESS_ENTITY | B21: A2ABBA5A-0035-4CE3-AF5C-CDF4CC070A03 | C21: MTED_EDaM_Design_Status | D21: SHL_CDM_EntityPropertyExtension.MTED_EDaM_Design_Status | E21: Draft | G21: Entity | H21: Not Verified - No Injection Result | I21: Not Applied | J21: No injection result recorded for this value.
A22: HR Organisation | B22: 15FFFED0-C988-44F0-8B8E-85C56A97663D | C22: PD_ObjectID | E22: 15FFFED0-C988-44F0-8B8E-85C56A97663D | G22: Entity | H22: Not Verified - No Injection Result | I22: Not Applied | J22: No injection result recorded for this value.
A23: HR Organisation | B23: 15FFFED0-C988-44F0-8B8E-85C56A97663D | C23: PD_SourceExtraction | E23: 46603045 | G23: Entity | H23: Not Verified - No Injection Result | I23: Not Applied | J23: No injection result recorded for this value.
A24: HR Organisation | B24: 15FFFED0-C988-44F0-8B8E-85C56A97663D | C24: PD_SourceModel | E24: 02_logistics_segment | G24: Entity | H24: Not Verified - No Injection Result | I24: Not Applied | J24: No injection result recorded for this value.
A25: HR Organisation | B25: 15FFFED0-C988-44F0-8B8E-85C56A97663D | C25: MTED_EDaM_Entity_Data_Category | D25: SHL_CDM_EntityPropertyExtension.MTED_EDaM_Entity_Data_Category | E25: <unspecified> | G25: Entity | H25: Not Verified - No Injection Result | I25: Not Applied | J25: No injection result recorded for this value.
A26: HR Organisation | B26: 15FFFED0-C988-44F0-8B8E-85C56A97663D | C26: MTED_EDaM_Security_Classification | D26: SHL_CDM_EntityPropertyExtension.MTED_EDaM_Security_Classification | E26: <unspecified> | G26: Entity | H26: Not Verified - No Injection Result | I26: Not Applied | J26: No injection result recorded for this value.
A27: HR Organisation | B27: 15FFFED0-C988-44F0-8B8E-85C56A97663D | C27: MTED_EDaM_Design_Status | D27: SHL_CDM_EntityPropertyExtension.MTED_EDaM_Design_Status | E27: Draft | G27: Entity | H27: Not Verified - No Injection Result | I27: Not Applied | J27: No injection result recorded for this value.
A28: Financial Organisation | B28: C5B7493D-E1F9-4A97-A533-B5F09CC3387D | C28: PD_ObjectID | E28: C5B7493D-E1F9-4A97-A533-B5F09CC3387D | G28: Entity | H28: Not Verified - No Injection Result | I28: Not Applied | J28: No injection result recorded for this value.
A29: Financial Organisation | B29: C5B7493D-E1F9-4A97-A533-B5F09CC3387D | C29: PD_SourceExtraction | E29: 46603045 | G29: Entity | H29: Not Verified - No Injection Result | I29: Not Applied | J29: No injection result recorded for this value.
A30: Financial Organisation | B30: C5B7493D-E1F9-4A97-A533-B5F09CC3387D | C30: PD_SourceModel | E30: 02_logistics_segment | G30: Entity | H30: Not Verified - No Injection Result | I30: Not Applied | J30: No injection result recorded for this value.
A31: Financial Organisation | B31: C5B7493D-E1F9-4A97-A533-B5F09CC3387D | C31: MTED_EDaM_Entity_Data_Category | D31: SHL_CDM_EntityPropertyExtension.MTED_EDaM_Entity_Data_Category | E31: <unspecified> | G31: Entity | H31: Not Verified - No Injection Result | I31: Not Applied | J31: No injection result recorded for this value.
A32: Financial Organisation | B32: C5B7493D-E1F9-4A97-A533-B5F09CC3387D | C32: MTED_EDaM_Security_Classification | D32: SHL_CDM_EntityPropertyExtension.MTED_EDaM_Security_Classification | E32: <unspecified> | G32: Entity | H32: Not Verified - No Injection Result | I32: Not Applied | J32: No injection result recorded for this value.
A33: Financial Organisation | B33: C5B7493D-E1F9-4A97-A533-B5F09CC3387D | C33: MTED_EDaM_Design_Status | D33: SHL_CDM_EntityPropertyExtension.MTED_EDaM_Design_Status | E33: Draft | G33: Entity | H33: Not Verified - No Injection Result | I33: Not Applied | J33: No injection result recorded for this value.
A34: Management Organisation | B34: 88C8F6B2-F0A1-48E0-A672-DB86B1E276B2 | C34: PD_ObjectID | E34: 88C8F6B2-F0A1-48E0-A672-DB86B1E276B2 | G34: Entity | H34: Not Verified - No Injection Result | I34: Not Applied | J34: No injection result recorded for this value.
A35: Management Organisation | B35: 88C8F6B2-F0A1-48E0-A672-DB86B1E276B2 | C35: PD_SourceExtraction | E35: 46603045 | G35: Entity | H35: Not Verified - No Injection Result | I35: Not Applied | J35: No injection result recorded for this value.
A36: Management Organisation | B36: 88C8F6B2-F0A1-48E0-A672-DB86B1E276B2 | C36: PD_SourceModel | E36: 02_logistics_segment | G36: Entity | H36: Not Verified - No Injection Result | I36: Not Applied | J36: No injection result recorded for this value.
A37: Management Organisation | B37: 88C8F6B2-F0A1-48E0-A672-DB86B1E276B2 | C37: MTED_EDaM_Entity_Data_Category | D37: SHL_CDM_EntityPropertyExtension.MTED_EDaM_Entity_Data_Category | E37: <unspecified> | G37: Entity | H37: Not Verified - No Injection Result | I37: Not Applied | J37: No injection result recorded for this value.
A38: Management Organisation | B38: 88C8F6B2-F0A1-48E0-A672-DB86B1E276B2 | C38: MTED_EDaM_Security_Classification | D38: SHL_CDM_EntityPropertyExtension.MTED_EDaM_Security_Classification | E38: <unspecified> | G38: Entity | H38: Not Verified - No Injection Result | I38: Not Applied | J38: No injection result recorded for this value.
A39: Management Organisation | B39: 88C8F6B2-F0A1-48E0-A672-DB86B1E276B2 | C39: MTED_EDaM_Design_Status | D39: SHL_CDM_EntityPropertyExtension.MTED_EDaM_Design_Status | E39: Draft | G39: Entity | H39: Not Verified - No Injection Result | I39: Not Applied | J39: No injection result recorded for this value.
A40: Sales Organisation | B40: 45C45241-9807-4055-96C5-007D465F4820 | C40: PD_ObjectID | E40: 45C45241-9807-4055-96C5-007D465F4820 | G40: Entity | H40: Not Verified - No Injection Result | I40: Not Applied | J40: No injection result recorded for this value.
...

Sheet UDP_EXCEPTIONS
A1: Severity | B1: Category | C1: Entity | D1: UDP | E1: Detail | F1: Recommended Action
A2: Medium | B2: Not verified | E2: 1177 rows in this category; the first 100 are listed above. | F2: Filter the Value Reconciliation sheet for the full list.
A3: Medium | B3: Not verified | C3: AIRWORTHINESS | D3: PD_ObjectID | E3: No injection result was recorded for this value. | F3: Re-run batch_run.py so the report is built from a live injection result.
A4: Medium | B4: Not verified | C4: AIRWORTHINESS | D4: PD_SourceExtraction | E4: No injection result was recorded for this value. | F4: Re-run batch_run.py so the report is built from a live injection result.
A5: Medium | B5: Not verified | C5: AIRWORTHINESS | D5: PD_SourceModel | E5: No injection result was recorded for this value. | F5: Re-run batch_run.py so the report is built from a live injection result.
A6: Medium | B6: Not verified | C6: AIRWORTHINESS | D6: MTED_EDaM_Entity_Data_Category | E6: No injection result was recorded for this value. | F6: Re-run batch_run.py so the report is built from a live injection result.
A7: Medium | B7: Not verified | C7: AIRWORTHINESS | D7: MTED_EDaM_Security_Classification | E7: No injection result was recorded for this value. | F7: Re-run batch_run.py so the report is built from a live injection result.
A8: Medium | B8: Not verified | C8: AIRWORTHINESS | D8: MTED_EDaM_Design_Status | E8: No injection result was recorded for this value. | F8: Re-run batch_run.py so the report is built from a live injection result.
A9: Medium | B9: Not verified | C9: ALLOTMENT | D9: PD_ObjectID | E9: No injection result was recorded for this value. | F9: Re-run batch_run.py so the report is built from a live injection result.
A10: Medium | B10: Not verified | C10: ALLOTMENT | D10: PD_SourceExtraction | E10: No injection result was recorded for this value. | F10: Re-run batch_run.py so the report is built from a live injection result.
A11: Medium | B11: Not verified | C11: ALLOTMENT | D11: PD_SourceModel | E11: No injection result was recorded for this value. | F11: Re-run batch_run.py so the report is built from a live injection result.
A12: Medium | B12: Not verified | C12: ALLOTMENT | D12: MTED_EDaM_Entity_Data_Category | E12: No injection result was recorded for this value. | F12: Re-run batch_run.py so the report is built from a live injection result.
A13: Medium | B13: Not verified | C13: ALLOTMENT | D13: MTED_EDaM_Security_Classification | E13: No injection result was recorded for this value. | F13: Re-run batch_run.py so the report is built from a live injection result.
A14: Medium | B14: Not verified | C14: ALLOTMENT | D14: MTED_EDaM_Design_Status | E14: No injection result was recorded for this value. | F14: Re-run batch_run.py so the report is built from a live injection result.
... A102: Medium | B102: Not verified | C102: BUSINESS_ENTITY_BUSINESS_AREA_ASSOCIATION | D102: MTED_EDaM_Entity_Maps_To_Entity | E102: No injection result was recorded for this value. | F102: Re-run batch_run.py so the report is built from a live injection result.
A103: Low | B103: Inferred value list | D103: MTED_EDaM_Entity_Data_Category | E103: The permitted values were inferred from observed data, not from BIM-core.xem. Observed is not the same as permitted. | F103: Confirm the list against BIM-core.xem before sign-off.
A104: Low | B104: Inferred value list | D104: MTED_EDaM_Security_Classification | E104: The permitted values were inferred from observed data, not from BIM-core.xem. Observed is not the same as permitted. | F104: Confirm the list against BIM-core.xem before sign-off.
A105: Low | B105: Inferred value list | D105: MTED_EDaM_Design_Status | E105: The permitted values were inferred from observed data, not from BIM-core.xem. Observed is not the same as permitted. | F105: Confirm the list against BIM-core.xem before sign-off.
A106: Low | B106: Inferred value list | D106: MTED_EDaM_Data_Owner | E106: The permitted values were inferred from observed data, not from BIM-core.xem. Observed is not the same as permitted. | F106: Confirm the list against BIM-core.xem before sign-off.
A107: Low | B107: Inferred value list | D107: DataSourcePersist | E107: The permitted values were inferred from observed data, not from BIM-core.xem. Observed is not the same as permitted. | F107: Confirm the list against BIM-core.xem before sign-off.
A108: Low | B108: Inferred value list | D108: ImportedType | E108: The permitted values were inferred from observed data, not from BIM-core.xem. Observed is not the same as permitted. | F108: Confirm the list against BIM-core.xem before sign-off.
A109: Low | B109: Inferred value list | D109: PersistBooleanMapping | E109: The permitted values were inferred from observed data, not from BIM-core.xem. Observed is not the same as permitted. | F109: Confirm the list against BIM-core.xem before sign-off.
A110: Low | B110: Inferred value list | D110: ColumnKind | E110: The permitted values were inferred from observed data, not from BIM-core.xem. Observed is not the same as permitted. | F110: Confirm the list against BIM-core.xem before sign-off.
A111: Low | B111: Inferred value list | D111: Attribute | E111: The permitted values were inferred from observed data, not from BIM-core.xem. Observed is not the same as permitted. | F111: Confirm the list against BIM-core.xem before sign-off.
A112: Informational | B112: Not carried by the erwin bridge | D112: Glossary term bindings (UseTerm) | E112: 2 term shortcuts - NOT delivered - external .glm has no erwin equivalent | F112: NOT RECOVERABLE as-is. SOW covers under 'naming standards, macros, templates - not automatically migrated'. Re-establish in erwin Naming Standards or relocate to Collibra.
A113: Informational | B113: Not carried by the erwin bridge | D113: GTL templates (relationship assertion, FK naming) | E113: 1 - NOT delivered | F113: NOT RECOVERABLE. SOW covers under 'model macros - manual rewrite required'.
A114: Informational | B114: Not carried by the erwin bridge | D114: Repository version history / branch | E114: extraction n/a - NOT delivered - point-in-time extract only | F114: OUT OF SCOPE per SOW: 'version history & audit lineage lost'. Archive PD repository read-only.

Sheet UDP_COMPARISON_SUMMARY
A1: UDP Comparison - SAP PowerDesigner vs erwin - 02_logistics_segment
A3: Run Information
A4: Report generated | B4: 2026-09-04 19:47:04
A5: Model | B5: 02_logistics_segment
A6: Model type | B6: CDM
A7: Source SAP model | B7: C:\Users\Shivansh\Downloads\migration-platform_4_sept_final\sappdmodels\cdm\02_logistics_segment.cdm
A8: erwin model compared | B8: app\udp_tool\output_erwin_models\02_logistics_segment.erwin
A9: erwin readback method | B9: binary | C9: See the Diagnostics sheet.
A11: Comparison
A12: UDP values compared | B12: =MAX(0,COUNTA(UDP_COMPARISON!$C:$C)-1)
A13: PASS | B13: =COUNTIF(UDP_COMPARISON!$F$2:$F$1178,"PASS") | C13: erwin holds exactly the value PowerDesigner held.
A14: MISMATCH | B14: =COUNTIF(UDP_COMPARISON!$F$2:$F$1178,"MISMATCH") | C14: erwin holds a different value.
A15: MISSING | B15: =COUNTIF(UDP_COMPARISON!$F$2:$F$1178,"MISSING") | C15: PowerDesigner had a value; erwin holds nothing.
A16: BLANK IN SAP | B16: =COUNTIF(UDP_COMPARISON!$F$2:$F$1178,"BLANK IN SAP") | C16: Nothing to migrate, so erwin holding nothing is correct. Excluded from the pass rate.
A17: EXTRA IN ERWIN | B17: =COUNTIF(UDP_COMPARISON!$F$2:$F$1178,"EXTRA IN ERWIN") | C17: erwin holds a value with no matching source row.
A19: Result
A20: Comparable values | B20: =B13+B14+B15 | C20: PASS + MISMATCH + MISSING. Blank source values are not a migration outcome, so they are not counted here.
A21: Pass rate | B21: =IF(B20=0,0,B13/B20)
A22: Verdict | B22: =IF(B20=0,"NO SOURCE VALUES TO MIGRATE",IF(B13=B20,"PASS",IF(B13=0,"FAIL - NO VALUES MATCHED","REVIEW REQUIRED"))) | C22: PASS only when every migratable value matches erwin exactly.
A24: Counts are live formulas over the UDP Comparison sheet, bounded to the rows this run wrote.

Sheet UDP_COMPARISON
A1: Entity Name | B1: Applied To | C1: UDP Name | D1: SAP Value | E1: erwin Value | F1: Status | G1: Source Path | H1: Note
A2: AIRWORTHINESS | B2: Entity | C2: MTED_EDaM_Design_Status | D2: Draft | E2: Draft | F2: PASS | G2: SHL_CDM_EntityPropertyExtension.MTED_EDaM_Design_Status
A3: AIRWORTHINESS | B3: Entity | C3: MTED_EDaM_Entity_Data_Category | D3: <unspecified> | E3: <unspecified> | F3: PASS | G3: SHL_CDM_EntityPropertyExtension.MTED_EDaM_Entity_Data_Category
A4: AIRWORTHINESS | B4: Entity | C4: MTED_EDaM_Security_Classification | D4: <unspecified> | E4: <unspecified> | F4: PASS | G4: SHL_CDM_EntityPropertyExtension.MTED_EDaM_Security_Classification
A5: AIRWORTHINESS | B5: Entity | C5: PD_ObjectID | D5: 36CAD75B-1BA6-4BD3-A129-C13DB1660312 | E5: 36CAD75B-1BA6-4BD3-A129-C13DB1660312 | F5: PASS
A6: AIRWORTHINESS | B6: Entity | C6: PD_SourceExtraction | D6: 46603045 | E6: 46603045 | F6: PASS
A7: AIRWORTHINESS | B7: Entity | C7: PD_SourceModel | D7: 02_logistics_segment | E7: 02_logistics_segment | F7: PASS
A8: ALLOTMENT | B8: Entity | C8: MTED_EDaM_Design_Status | D8: Draft | E8: Draft | F8: PASS | G8: SHL_CDM_EntityPropertyExtension.MTED_EDaM_Design_Status
A9: ALLOTMENT | B9: Entity | C9: MTED_EDaM_Entity_Data_Category | D9: <unspecified> | E9: <unspecified> | F9: PASS | G9: SHL_CDM_EntityPropertyExtension.MTED_EDaM_Entity_Data_Category
A10: ALLOTMENT | B10: Entity | C10: MTED_EDaM_Security_Classification | D10: <unspecified> | E10: <unspecified> | F10: PASS | G10: SHL_CDM_EntityPropertyExtension.MTED_EDaM_Security_Classification
A11: ALLOTMENT | B11: Entity | C11: PD_ObjectID | D11: 0345D9B5-61B1-48AE-951B-B076025454F8 | E11: 0345D9B5-61B1-48AE-951B-B076025454F8 | F11: PASS
A12: ALLOTMENT | B12: Entity | C12: PD_SourceExtraction | D12: 46603045 | E12: 46603045 | F12: PASS
A13: ALLOTMENT | B13: Entity | C13: PD_SourceModel | D13: 02_logistics_segment | E13: 02_logistics_segment | F13: PASS
A14: AUTHOURISATION_STATUS | B14: Entity | C14: MTED_EDaM_Design_Status | D14: Draft | E14: Draft | F14: PASS | G14: SHL_CDM_EntityPropertyExtension.MTED_EDaM_Design_Status
A15: AUTHOURISATION_STATUS | B15: Entity | C15: MTED_EDaM_Entity_Data_Category | D15: <unspecified> | E15: <unspecified> | F15: PASS | G15: SHL_CDM_EntityPropertyExtension.MTED_EDaM_Entity_Data_Category
A16: AUTHOURISATION_STATUS | B16: Entity | C16: MTED_EDaM_Security_Classification | D16: <unspecified> | E16: <unspecified> | F16: PASS | G16: SHL_CDM_EntityPropertyExtension.MTED_EDaM_Security_Classification
A17: AUTHOURISATION_STATUS | B17: Entity | C17: PD_ObjectID | D17: 0B133FF6-086D-4FD6-83B8-0F6DE3E5DE76 | E17: 0B133FF6-086D-4FD6-83B8-0F6DE3E5DE76 | F17: PASS
A18: AUTHOURISATION_STATUS | B18: Entity | C18: PD_SourceExtraction | D18: 46603045 | E18: 46603045 | F18: PASS
A19: AUTHOURISATION_STATUS | B19: Entity | C19: PD_SourceModel | D19: 02_logistics_segment | E19: 02_logistics_segment | F19: PASS
A20: BED | B20: Entity | C20: MTED_EDaM_Design_Status | D20: Draft | E20: Draft | F20: PASS | G20: SHL_CDM_EntityPropertyExtension.MTED_EDaM_Design_Status
A21: BED | B21: Entity | C21: MTED_EDaM_Entity_Data_Category | D21: <unspecified> | E21: <unspecified> | F21: PASS | G21: SHL_CDM_EntityPropertyExtension.MTED_EDaM_Entity_Data_Category
A22: BED | B22: Entity | C22: MTED_EDaM_Security_Classification | D22: <unspecified> | E22: <unspecified> | F22: PASS | G22: SHL_CDM_EntityPropertyExtension.MTED_EDaM_Security_Classification
A23: BED | B23: Entity | C23: PD_ObjectID | D23: 178002C1-3119-48E9-A913-FFBE0F800CD7 | E23: 178002C1-3119-48E9-A913-FFBE0F800CD7 | F23: PASS
A24: BED | B24: Entity | C24: PD_SourceExtraction | D24: 46603045 | E24: 46603045 | F24: PASS
A25: BED | B25: Entity | C25: PD_SourceModel | D25: 02_logistics_segment | E25: 02_logistics_segment | F25: PASS
A26: BED_TYPE | B26: Entity | C26: MTED_EDaM_Design_Status | D26: Draft | E26: Draft | F26: PASS | G26: SHL_CDM_EntityPropertyExtension.MTED_EDaM_Design_Status
A27: BED_TYPE | B27: Entity | C27: MTED_EDaM_Entity_Data_Category | D27: <unspecified> | E27: <unspecified> | F27: PASS | G27: SHL_CDM_EntityPropertyExtension.MTED_EDaM_Entity_Data_Category
A28: BED_TYPE | B28: Entity | C28: MTED_EDaM_Security_Classification | D28: <unspecified> | E28: <unspecified> | F28: PASS | G28: SHL_CDM_EntityPropertyExtension.MTED_EDaM_Security_Classification
A29: BED_TYPE | B29: Entity | C29: PD_ObjectID | D29: 72695689-DA9F-433D-BC07-BADC42E1101B | E29: 72695689-DA9F-433D-BC07-BADC42E1101B | F29: PASS
A30: BED_TYPE | B30: Entity | C30: PD_SourceExtraction | D30: 46603045 | E30: 46603045 | F30: PASS
A31: BED_TYPE | B31: Entity | C31: PD_SourceModel | D31: 02_logistics_segment | E31: 02_logistics_segment | F31: PASS
A32: BOOKING | B32: Entity | C32: MTED_EDaM_Design_Status | D32: Draft | E32: Draft | F32: PASS | G32: SHL_CDM_EntityPropertyExtension.MTED_EDaM_Design_Status
A33: BOOKING | B33: Entity | C33: MTED_EDaM_Entity_Data_Category | D33: <unspecified> | E33: <unspecified> | F33: PASS | G33: SHL_CDM_EntityPropertyExtension.MTED_EDaM_Entity_Data_Category
A34: BOOKING | B34: Entity | C34: MTED_EDaM_Security_Classification | D34: <unspecified> | E34: <unspecified> | F34: PASS | G34: SHL_CDM_EntityPropertyExtension.MTED_EDaM_Security_Classification
A35: BOOKING | B35: Entity | C35: PD_ObjectID | D35: 454AD190-DB27-42C5-B256-BC4323D4887F | E35: 454AD190-DB27-42C5-B256-BC4323D4887F | F35: PASS
A36: BOOKING | B36: Entity | C36: PD_SourceExtraction | D36: 46603045 | E36: 46603045 | F36: PASS
A37: BOOKING | B37: Entity | C37: PD_SourceModel | D37: 02_logistics_segment | E37: 02_logistics_segment | F37: PASS
A38: BOOKING_STATUS | B38: Entity | C38: MTED_EDaM_Design_Status | D38: Draft | E38: Draft | F38: PASS | G38: SHL_CDM_EntityPropertyExtension.MTED_EDaM_Design_Status
A39: BOOKING_STATUS | B39: Entity | C39: MTED_EDaM_Entity_Data_Category | D39: <unspecified> | E39: <unspecified> | F39: PASS | G39: SHL_CDM_EntityPropertyExtension.MTED_EDaM_Entity_Data_Category
A40: BOOKING_STATUS | B40: Entity | C40: MTED_EDaM_Security_Classification | D40: <unspecified> | E40: <unspecified> | F40: PASS | G40: SHL_CDM_EntityPropertyExtension.MTED_EDaM_Security_Classification
...

Sheet UDP_BY_UDP
A1: UDP Name | B1: Rows | C1: PASS | D1: MISMATCH | E1: MISSING | F1: BLANK IN SAP | G1: EXTRA IN ERWIN | H1: Pass Rate | I1: Verdict
A2: MTED_EDaM_Data_Owner | B2: =COUNTIF(UDP_COMPARISON!$C$2:$C$1178,$A2) | C2: =COUNTIFS(UDP_COMPARISON!$C$2:$C$1178,$A2,UDP_COMPARISON!$F$2:$F$1178,"PASS") | D2: =COUNTIFS(UDP_COMPARISON!$C$2:$C$1178,$A2,UDP_COMPARISON!$F$2:$F$1178,"MISMATCH") | E2: =COUNTIFS(UDP_COMPARISON!$C$2:$C$1178,$A2,UDP_COMPARISON!$F$2:$F$1178,"MISSING") | F2: =COUNTIFS(UDP_COMPARISON!$C$2:$C$1178,$A2,UDP_COMPARISON!$F$2:$F$1178,"BLANK IN SAP") | G2: =COUNTIFS(UDP_COMPARISON!$C$2:$C$1178,$A2,UDP_COMPARISON!$F$2:$F$1178,"EXTRA IN ERWIN") | H2: =IF(($C2+$D2+$E2)=0,0,$C2/($C2+$D2+$E2)) | I2: =IF(($C2+$D2+$E2)=0,"Nothing to migrate",IF($C2=($C2+$D2+$E2),"PASS",IF($C2=0,"FAIL - none matched","REVIEW REQUIRED")))
A3: MTED_EDaM_Design_Status | B3: =COUNTIF(UDP_COMPARISON!$C$2:$C$1178,$A3) | C3: =COUNTIFS(UDP_COMPARISON!$C$2:$C$1178,$A3,UDP_COMPARISON!$F$2:$F$1178,"PASS") | D3: =COUNTIFS(UDP_COMPARISON!$C$2:$C$1178,$A3,UDP_COMPARISON!$F$2:$F$1178,"MISMATCH") | E3: =COUNTIFS(UDP_COMPARISON!$C$2:$C$1178,$A3,UDP_COMPARISON!$F$2:$F$1178,"MISSING") | F3: =COUNTIFS(UDP_COMPARISON!$C$2:$C$1178,$A3,UDP_COMPARISON!$F$2:$F$1178,"BLANK IN SAP") | G3: =COUNTIFS(UDP_COMPARISON!$C$2:$C$1178,$A3,UDP_COMPARISON!$F$2:$F$1178,"EXTRA IN ERWIN") | H3: =IF(($C3+$D3+$E3)=0,0,$C3/($C3+$D3+$E3)) | I3: =IF(($C3+$D3+$E3)=0,"Nothing to migrate",IF($C3=($C3+$D3+$E3),"PASS",IF($C3=0,"FAIL - none matched","REVIEW REQUIRED")))
A4: MTED_EDaM_Entity_Data_Category | B4: =COUNTIF(UDP_COMPARISON!$C$2:$C$1178,$A4) | C4: =COUNTIFS(UDP_COMPARISON!$C$2:$C$1178,$A4,UDP_COMPARISON!$F$2:$F$1178,"PASS") | D4: =COUNTIFS(UDP_COMPARISON!$C$2:$C$1178,$A4,UDP_COMPARISON!$F$2:$F$1178,"MISMATCH") | E4: =COUNTIFS(UDP_COMPARISON!$C$2:$C$1178,$A4,UDP_COMPARISON!$F$2:$F$1178,"MISSING") | F4: =COUNTIFS(UDP_COMPARISON!$C$2:$C$1178,$A4,UDP_COMPARISON!$F$2:$F$1178,"BLANK IN SAP") | G4: =COUNTIFS(UDP_COMPARISON!$C$2:$C$1178,$A4,UDP_COMPARISON!$F$2:$F$1178,"EXTRA IN ERWIN") | H4: =IF(($C4+$D4+$E4)=0,0,$C4/($C4+$D4+$E4)) | I4: =IF(($C4+$D4+$E4)=0,"Nothing to migrate",IF($C4=($C4+$D4+$E4),"PASS",IF($C4=0,"FAIL - none matched","REVIEW REQUIRED")))
A5: MTED_EDaM_Entity_Maps_To_Entity | B5: =COUNTIF(UDP_COMPARISON!$C$2:$C$1178,$A5) | C5: =COUNTIFS(UDP_COMPARISON!$C$2:$C$1178,$A5,UDP_COMPARISON!$F$2:$F$1178,"PASS") | D5: =COUNTIFS(UDP_COMPARISON!$C$2:$C$1178,$A5,UDP_COMPARISON!$F$2:$F$1178,"MISMATCH") | E5: =COUNTIFS(UDP_COMPARISON!$C$2:$C$1178,$A5,UDP_COMPARISON!$F$2:$F$1178,"MISSING") | F5: =COUNTIFS(UDP_COMPARISON!$C$2:$C$1178,$A5,UDP_COMPARISON!$F$2:$F$1178,"BLANK IN SAP") | G5: =COUNTIFS(UDP_COMPARISON!$C$2:$C$1178,$A5,UDP_COMPARISON!$F$2:$F$1178,"EXTRA IN ERWIN") | H5: =IF(($C5+$D5+$E5)=0,0,$C5/($C5+$D5+$E5)) | I5: =IF(($C5+$D5+$E5)=0,"Nothing to migrate",IF($C5=($C5+$D5+$E5),"PASS",IF($C5=0,"FAIL - none matched","REVIEW REQUIRED")))
A6: MTED_EDaM_Security_Classification | B6: =COUNTIF(UDP_COMPARISON!$C$2:$C$1178,$A6) | C6: =COUNTIFS(UDP_COMPARISON!$C$2:$C$1178,$A6,UDP_COMPARISON!$F$2:$F$1178,"PASS") | D6: =COUNTIFS(UDP_COMPARISON!$C$2:$C$1178,$A6,UDP_COMPARISON!$F$2:$F$1178,"MISMATCH") | E6: =COUNTIFS(UDP_COMPARISON!$C$2:$C$1178,$A6,UDP_COMPARISON!$F$2:$F$1178,"MISSING") | F6: =COUNTIFS(UDP_COMPARISON!$C$2:$C$1178,$A6,UDP_COMPARISON!$F$2:$F$1178,"BLANK IN SAP") | G6: =COUNTIFS(UDP_COMPARISON!$C$2:$C$1178,$A6,UDP_COMPARISON!$F$2:$F$1178,"EXTRA IN ERWIN") | H6: =IF(($C6+$D6+$E6)=0,0,$C6/($C6+$D6+$E6)) | I6: =IF(($C6+$D6+$E6)=0,"Nothing to migrate",IF($C6=($C6+$D6+$E6),"PASS",IF($C6=0,"FAIL - none matched","REVIEW REQUIRED")))
A7: PD_ObjectID | B7: =COUNTIF(UDP_COMPARISON!$C$2:$C$1178,$A7) | C7: =COUNTIFS(UDP_COMPARISON!$C$2:$C$1178,$A7,UDP_COMPARISON!$F$2:$F$1178,"PASS") | D7: =COUNTIFS(UDP_COMPARISON!$C$2:$C$1178,$A7,UDP_COMPARISON!$F$2:$F$1178,"MISMATCH") | E7: =COUNTIFS(UDP_COMPARISON!$C$2:$C$1178,$A7,UDP_COMPARISON!$F$2:$F$1178,"MISSING") | F7: =COUNTIFS(UDP_COMPARISON!$C$2:$C$1178,$A7,UDP_COMPARISON!$F$2:$F$1178,"BLANK IN SAP") | G7: =COUNTIFS(UDP_COMPARISON!$C$2:$C$1178,$A7,UDP_COMPARISON!$F$2:$F$1178,"EXTRA IN ERWIN") | H7: =IF(($C7+$D7+$E7)=0,0,$C7/($C7+$D7+$E7)) | I7: =IF(($C7+$D7+$E7)=0,"Nothing to migrate",IF($C7=($C7+$D7+$E7),"PASS",IF($C7=0,"FAIL - none matched","REVIEW REQUIRED")))
A8: PD_SourceExtraction | B8: =COUNTIF(UDP_COMPARISON!$C$2:$C$1178,$A8) | C8: =COUNTIFS(UDP_COMPARISON!$C$2:$C$1178,$A8,UDP_COMPARISON!$F$2:$F$1178,"PASS") | D8: =COUNTIFS(UDP_COMPARISON!$C$2:$C$1178,$A8,UDP_COMPARISON!$F$2:$F$1178,"MISMATCH") | E8: =COUNTIFS(UDP_COMPARISON!$C$2:$C$1178,$A8,UDP_COMPARISON!$F$2:$F$1178,"MISSING") | F8: =COUNTIFS(UDP_COMPARISON!$C$2:$C$1178,$A8,UDP_COMPARISON!$F$2:$F$1178,"BLANK IN SAP") | G8: =COUNTIFS(UDP_COMPARISON!$C$2:$C$1178,$A8,UDP_COMPARISON!$F$2:$F$1178,"EXTRA IN ERWIN") | H8: =IF(($C8+$D8+$E8)=0,0,$C8/($C8+$D8+$E8)) | I8: =IF(($C8+$D8+$E8)=0,"Nothing to migrate",IF($C8=($C8+$D8+$E8),"PASS",IF($C8=0,"FAIL - none matched","REVIEW REQUIRED")))
A9: PD_SourceModel | B9: =COUNTIF(UDP_COMPARISON!$C$2:$C$1178,$A9) | C9: =COUNTIFS(UDP_COMPARISON!$C$2:$C$1178,$A9,UDP_COMPARISON!$F$2:$F$1178,"PASS") | D9: =COUNTIFS(UDP_COMPARISON!$C$2:$C$1178,$A9,UDP_COMPARISON!$F$2:$F$1178,"MISMATCH") | E9: =COUNTIFS(UDP_COMPARISON!$C$2:$C$1178,$A9,UDP_COMPARISON!$F$2:$F$1178,"MISSING") | F9: =COUNTIFS(UDP_COMPARISON!$C$2:$C$1178,$A9,UDP_COMPARISON!$F$2:$F$1178,"BLANK IN SAP") | G9: =COUNTIFS(UDP_COMPARISON!$C$2:$C$1178,$A9,UDP_COMPARISON!$F$2:$F$1178,"EXTRA IN ERWIN") | H9: =IF(($C9+$D9+$E9)=0,0,$C9/($C9+$D9+$E9)) | I9: =IF(($C9+$D9+$E9)=0,"Nothing to migrate",IF($C9=($C9+$D9+$E9),"PASS",IF($C9=0,"FAIL - none matched","REVIEW REQUIRED")))

Sheet UDP_DIAGNOSTICS
A1: Diagnostics - how erwin was read, and whether to trust it
A2: erwin model read | B2: app\udp_tool\output_erwin_models\02_logistics_segment.erwin
A3: Readback method | B3: binary | C3: 'com' asks erwin directly and is authoritative. 'binary' decodes the .erwin file offline - independent of the API that wrote the data, but reverse-engineered, so it is a cross-check.
A4: Readback trustworthy | B4: Yes | C4: When No, the comparison is not reported as mismatches - the reading itself is in doubt.
A5: Decoder self-test | B5: 1 | C5: Share of decoded values that pair with a source value. A low score means the property slot mapping is wrong for this erwin build, not that the data is wrong.
A6: Objects read from erwin | B6: 195
A7: UDP values read from erwin | B7: 1177
A9: Readback notes
A10: - | B10: Fell back to the offline decoder (pywin32 is not installed, so erwin cannot be queried (No module named 'pythoncom'). Use --readback binary for an offline cross-check.)
A11: - | B11: Decoder self-test: 1177/1177 paired values agree (100.0%); slot mapping confirmed.
A13: Source data warnings
A14: - | B14: None.
