Workbook

Sheet V3_OVERVIEW
A1: V3 — Final Fidelity Report
A2: Reconciliation of the source model against the enriched erwin V2, scored with the enrichment evidence, and the PASS/FAIL verdict.
A4: Measure | B4: Value | C4: Where it comes from
A5: Model | B5: 03_Lubes_Indirect_Sales_Marketing_Portfolio_LDM
A6: Model type | B6: LDM
A7: SAP PD file | B7: 03_Lubes_Sales_Marketing_Indirect_Channel_Portfolio_LDM_updated.ldm
A8: erwin file reconciled | B8: 03_Lubes_Sales_Marketing_Indirect_Channel_Portfolio_LDM_updated.xml
A10: FIDELITY PROGRESSION | C10: Each stage is measured against a different erwin artefact and recomputed in full
A11: V1 fidelity % (initial migration) | B11: n/a | C11: SAP PD vs erwin XML V1 — comments not injected, no UDPs written — not measured for this model
A12: V2 fidelity % (after preprocessing) | B12: 98.97 | C12: SAP PD vs the preprocessed erwin XML — Comments/Notes or repairs
A13: components | B13: structural=98.45%, documentation=100.00%, udp=n/a | C13: Not measurable for this model, weights renormalised: udp.
A14: V3 fidelity % (after enrichment) | B14: 98.97 | C14: UDP component read back from the enriched erwin model
A15: components | B15: structural=98.45%, documentation=100.00%, udp=n/a | C15: Not measurable for this model, weights renormalised: udp.
A17: COMPONENTS AT V3
A18: Structural fidelity % | B18: 98.45 | C18: Entities/Tables, Attributes/Columns, Relationships and Keys
A19: Documentation fidelity % | B19: 100 | C19: Comments / Notes, Descriptions and Annotations
A20: UDP mapping pass rate % (.erwin) | B20: n/a | C20: Read back from the enriched erwin model — this feeds the V3 score
A21: UDP fidelity % (erwin XML) | B21: n/a | C21: udp_fidelity.py scores the XML export, which carries no UDPs
A22: Shortcut fidelity % | B22: n/a | C22: Not measured: erwin's XML export has no shortcut object
A23: Tag fidelity % | B23: n/a | C23: Not measured: erwin Tags have no representation in this framework
A25: ENRICHMENT
A26: UDP values compared | B26: 0
A27: UDP verdict | B27: NOT COMPARED
A28: UDP stage | B28: EXTRACTED | C28: SKIPPED / EXTRACTED / INJECTED / COMPARED / FAILED
A29: UDPs injected into erwin | B29: No
A30: erwin binary read back | B30: n/a
A31: Read-back reliable | B31: n/a | C31: The binary decoder scores itself and refuses to report below 80%
A33: FINDINGS
A34: Errors (CRITICAL) | B34: 0
A35: Warnings | B35: 10
A36: Information | B36: 15
A38: VERDICT
A39: Status | B39: PASS
A40: Destination | B40: 3_final
A41: Gate note | B41: PASS: overall fidelity 98.97% >= 90.00% threshold (structural status was WARN: 0 CRITICAL, 10 WARNING finding(s) remain listed on the FINDINGS sheet)
A43: RELATED REPORTS
A44: V1 initial fidelity report | B44: 03_Lubes_Sales_Marketing_Indirect_Channel_Portfolio_LDM_updated_V1_Initial_Fidelity_Report.xlsx
A45: V2 UDP mapping report | B45: 03_Lubes_Sales_Marketing_Indirect_Channel_Portfolio_LDM_updated_V2_UDP_Mapping_Report.xlsx
A46: UDP notes | B46: Mapped 3 UDP definition(s) and 90 property value(s). | No source .erwin binary found; injection skipped. Save the model as <name>.erwin next to its XML export in erwinmodels/1_initial/erwin/. | No .erwin binary available to read back; comparison skipped.

Sheet SUMMARY
A1: SAP PD (PowerDesigner LDM) -> erwin | Logical Model Validation Report | generated 2026-09-05 21:17
A2: # | B2: SAP PD File | C2: erwin File | D2: SAP PD Model | E2: erwin Model | F2: Status | G2: Fidelity % | H2: Review? | I2: Entities (SAP PD) | J2: Entities (erwin) | K2: Entities Matched | L2: Ent. Missing | M2: Ent. Extra | N2: Attrs (SAP PD) | O2: Attrs (erwin) | P2: Attrs Matched | Q2: Attr Missing | R2: Attr Extra | S2: Rels (SAP PD) | T2: Rels (erwin) | U2: Rels Matched | V2: Rel Missing | W2: Rel Extra | X2: Hierarchies (SAP PD) | Y2: Hierarchies (erwin) | Z2: Identifiers (SAP PD) | AA2: Identifiers (erwin) | AB2: Domains (SAP PD) | AC2: Domains (erwin) | AD2: Shortcuts (SAP PD) | AE2: Shortcuts (erwin) | AF2: CRITICAL | AG2: WARNING | AH2: INFO
A3: 1 | B3: 03_Lubes_Sales_Marketing_Indirect_Channel_Portfolio_LDM_updated.ldm | C3: 03_Lubes_Sales_Marketing_Indirect_Channel_Portfolio_LDM_updated.xml | D3: 03_Lubes_Indirect_Sales_Marketing_Portfolio_LDM | E3: 03_Lubes_Indirect_Sales_Marketing_Portfolio_LDM | F3: PASS | G3: 98.97 | I3: 30 | J3: 30 | K3: 30 | L3: 0 | M3: 0 | N3: 182 | O3: 182 | P3: 182 | Q3: 0 | R3: 0 | S3: 42 | T3: 42 | U3: 42 | V3: 0 | W3: 0 | X3: 0 | Y3: 0 | Z3: 20 | AA3: 20 | AB3: 0 | AC3: 0 | AD3: 0 | AE3: 0 | AF3: 0 | AG3: 10 | AH3: 15
A4: TOTAL | G4: 98.97 | I4: 30 | J4: 30 | K4: 30 | L4: 0 | M4: 0 | N4: 182 | O4: 182 | P4: 182 | Q4: 0 | R4: 0 | S4: 42 | T4: 42 | U4: 42 | V4: 0 | W4: 0 | X4: 0 | Y4: 0 | Z4: 20 | AA4: 20 | AB4: 0 | AC4: 0 | AD4: 0 | AE4: 0 | AF4: 0 | AG4: 10 | AH4: 15

Sheet DASHBOARD
A1: Migration Reconciliation Dashboard
A3: Run Statistic | B3: Value | H3: Findings by severity
A4: Models validated | B4: 1 | H4: CRITICAL | I4: 0
A5: PASS | B5: 1 | H5: WARNING | I5: 10
A6: WARN | B6: 0 | H6: INFO | I6: 15
A7: FAIL | B7: 0 | H7: VERIFIED | I7: 20
A8: ERROR | B8: 0
A9: Average fidelity score | B9: 98.97
A10: Models needing review | B10: 0
A11: Total findings | B11: 45
A12: CRITICAL findings | B12: 0
A13: WARNING findings | B13: 10
A14: INFO findings | B14: 15
A15: Entities compared | B15: 30
A16: Attributes compared | B16: 182
A17: Relationships compared | B17: 42
A19: Lowest-fidelity models
A20: Model | B20: Status | C20: Fidelity % | D20: CRITICAL | E20: WARNING
A21: 03_Lubes_Sales_Marketing_Indirect_Channel_Portfolio_LDM_updated.ldm | B21: PASS | C21: 98.97 | D21: 20 | E21: 20 | F21: 0 | G21: 0 | H21: 0 | I21: 0 | J21: 10

Sheet FINDINGS
A1: Model | B1: Status | C1: Severity | D1: Category | E1: Object Type | F1: Object | G1: Member | H1: Message | I1: SAP PD Value | J1: erwin Value | K1: Recommended Action | L1: Manual Review
A2: 03_Lubes_Sales_Marketing_Indirect_Channel_Portfolio_LDM_updated.ldm | B2: PASS | C2: WARNING | D2: DATA_TYPE | E2: ATTRIBUTE | F2: CUSTOMER (CSTMR) | G2: CSTMR_MSTR_ID | H2: Logical data type differs (compared at approved PD→erwin type matrix) | I2: VARCHAR / TEXT | J2: CHAR(18) / TEXT | K2: Reassign the erwin logical datatype or domain so both sides express the same logical type family.
A3: 03_Lubes_Sales_Marketing_Indirect_Channel_Portfolio_LDM_updated.ldm | B3: PASS | C3: WARNING | D3: DATA_TYPE | E3: ATTRIBUTE | F3: CUSTOMER (CSTMR) | G3: CSTMR_NM | H3: Logical data type differs (compared at approved PD→erwin type matrix) | I3: VARCHAR(2) / TEXT | J3: CHAR(18) / TEXT | K3: Reassign the erwin logical datatype or domain so both sides express the same logical type family.
A4: 03_Lubes_Sales_Marketing_Indirect_Channel_Portfolio_LDM_updated.ldm | B4: PASS | C4: WARNING | D4: DATA_TYPE | E4: ATTRIBUTE | F4: DISTRIBUTOR | G4: CRRNT_STTS | H4: Logical data type differs (compared at approved PD→erwin type matrix) | I4: nvarchar(10) → VARCHAR(10) / TEXT | J4: CHAR(18) / TEXT | K4: Reassign the erwin logical datatype or domain so both sides express the same logical type family.
A5: 03_Lubes_Sales_Marketing_Indirect_Channel_Portfolio_LDM_updated.ldm | B5: PASS | C5: WARNING | D5: DATA_TYPE | E5: ATTRIBUTE | F5: DISTRIBUTOR | G5: DISTRIBUTOR_CD | H5: Logical data type differs (compared at approved PD→erwin type matrix) | I5: nvarchar(10) → VARCHAR(10) / TEXT | J5: CHAR(18) / TEXT | K5: Reassign the erwin logical datatype or domain so both sides express the same logical type family.
A6: 03_Lubes_Sales_Marketing_Indirect_Channel_Portfolio_LDM_updated.ldm | B6: PASS | C6: WARNING | D6: DATA_TYPE | E6: ATTRIBUTE | F6: DISTRIBUTOR | G6: DISTRIBUTOR_NM | H6: Logical data type differs (compared at approved PD→erwin type matrix) | I6: nvarchar(100) → VARCHAR(100) / TEXT | J6: CHAR(18) / TEXT | K6: Reassign the erwin logical datatype or domain so both sides express the same logical type family.
A7: 03_Lubes_Sales_Marketing_Indirect_Channel_Portfolio_LDM_updated.ldm | B7: PASS | C7: WARNING | D7: DATA_TYPE | E7: ATTRIBUTE | F7: SALES_AREA (SLS_AR) | G7: CSTMR_MSTR_ID | H7: Logical data type differs (compared at approved PD→erwin type matrix) | I7: VARCHAR / TEXT | J7: CHAR(18) / TEXT | K7: Reassign the erwin logical datatype or domain so both sides express the same logical type family.
A8: 03_Lubes_Sales_Marketing_Indirect_Channel_Portfolio_LDM_updated.ldm | B8: PASS | C8: WARNING | D8: DATA_TYPE | E8: ATTRIBUTE | F8: SALES_AREA (SLS_AR) | G8: DSTRBTN_CHNNL | H8: Logical data type differs (compared at approved PD→erwin type matrix) | I8: VARCHAR / TEXT | J8: CHAR(18) / TEXT | K8: Reassign the erwin logical datatype or domain so both sides express the same logical type family.
A9: 03_Lubes_Sales_Marketing_Indirect_Channel_Portfolio_LDM_updated.ldm | B9: PASS | C9: WARNING | D9: DATA_TYPE | E9: ATTRIBUTE | F9: SALES_AREA (SLS_AR) | G9: SLS_ORGNZTN_ID | H9: Logical data type differs (compared at 'family' strictness) | I9: VARCHAR> / OTHER | J9: CHAR(18) / TEXT | K9: Reassign the erwin logical datatype or domain so both sides express the same logical type family.
A10: 03_Lubes_Sales_Marketing_Indirect_Channel_Portfolio_LDM_updated.ldm | B10: PASS | C10: WARNING | D10: DATA_TYPE | E10: ATTRIBUTE | F10: SELL_IN_SALES_ORDER (SELL_IN_SLS_ORDR) | G10: DT | H10: Logical data type differs (compared at 'family' strictness) | I10: DATETIME / TEMPORAL | J10: CHAR(18) / TEXT | K10: Reassign the erwin logical datatype or domain so both sides express the same logical type family.
A11: 03_Lubes_Sales_Marketing_Indirect_Channel_Portfolio_LDM_updated.ldm | B11: PASS | C11: WARNING | D11: MODEL_QUALITY | E11: ENTITY | F11: RETAILER (RTLR) | H11: Entity participates in no relationship or hierarchy in erwin — possible orphan from the migration | J11: 0 relationships | K11: Reconnect the entity, or confirm it is genuinely standalone reference data.
A12: 03_Lubes_Sales_Marketing_Indirect_Channel_Portfolio_LDM_updated.ldm | B12: PASS | C12: INFO | D12: FALLBACK_MATCH | E12: ATTRIBUTE | F12: COUNTRY | G12: DISTRIBUTOR_ID | H12: erwin role-migrated key attribute — reconciled by the corresponding SAP PD relationship, which expresses the same foreign key without a separate attribute object | I12: — | J12: DISTRIBUTOR_ID | K12: No action required; informational only.
A13: 03_Lubes_Sales_Marketing_Indirect_Channel_Portfolio_LDM_updated.ldm | B13: PASS | C13: INFO | D13: FALLBACK_MATCH | E13: ATTRIBUTE | F13: DISTRIBUTOR | G13: CSTMR_MSTR_ID | H13: erwin role-migrated key attribute — reconciled by the corresponding SAP PD relationship, which expresses the same foreign key without a separate attribute object | I13: — | J13: CSTMR_MSTR_ID | K13: No action required; informational only.
A14: 03_Lubes_Sales_Marketing_Indirect_Channel_Portfolio_LDM_updated.ldm | B14: PASS | C14: INFO | D14: FALLBACK_MATCH | E14: ATTRIBUTE | F14: LEAD_CAMPAIGN | G14: CAMPAIGN_ | H14: erwin role-migrated key attribute — reconciled by the corresponding SAP PD relationship, which expresses the same foreign key without a separate attribute object | I14: — | J14: CAMPAIGN_ | K14: No action required; informational only.
A15: 03_Lubes_Sales_Marketing_Indirect_Channel_Portfolio_LDM_updated.ldm | B15: PASS | C15: INFO | D15: FALLBACK_MATCH | E15: ATTRIBUTE | F15: LEAD_CAMPAIGN | G15: CAMPAIGN_SOURCE_ID | H15: erwin role-migrated key attribute — reconciled by the corresponding SAP PD relationship, which expresses the same foreign key without a separate attribute object | I15: — | J15: CAMPAIGN_SOURCE_ID | K15: No action required; informational only.
A16: 03_Lubes_Sales_Marketing_Indirect_Channel_Portfolio_LDM_updated.ldm | B16: PASS | C16: INFO | D16: FALLBACK_MATCH | E16: ATTRIBUTE | F16: LEAD_CAMPAIGN | G16: LEAD_ID | H16: erwin role-migrated key attribute — reconciled by the corresponding SAP PD relationship, which expresses the same foreign key without a separate attribute object | I16: — | J16: LEAD_ID | K16: No action required; informational only.
A17: 03_Lubes_Sales_Marketing_Indirect_Channel_Portfolio_LDM_updated.ldm | B17: PASS | C17: INFO | D17: MODEL_QUALITY | E17: IDENTIFIER | F17: DISCOUNT | H17: Entity has no primary identifier in either model | I17: (none) | J17: (none) | K17: Pre-existing in SAP PD, not caused by the migration. Define a primary identifier if the business requires unique referencing.
A18: 03_Lubes_Sales_Marketing_Indirect_Channel_Portfolio_LDM_updated.ldm | B18: PASS | C18: INFO | D18: MODEL_QUALITY | E18: IDENTIFIER | F18: DISTRIBUTOR_ANNUAL_TARGET (DISTRIBUTOR_ANNL_TRGT) | H18: Entity has no primary identifier in either model | I18: (none) | J18: (none) | K18: Pre-existing in SAP PD, not caused by the migration. Define a primary identifier if the business requires unique referencing.
A19: 03_Lubes_Sales_Marketing_Indirect_Channel_Portfolio_LDM_updated.ldm | B19: PASS | C19: INFO | D19: MODEL_QUALITY | E19: IDENTIFIER | F19: DISTRIBUTOR_LEARNING (DISTRIBUTOR_LRNNG) | H19: Entity has no primary identifier in either model | I19: (none) | J19: (none) | K19: Pre-existing in SAP PD, not caused by the migration. Define a primary identifier if the business requires unique referencing.
A20: 03_Lubes_Sales_Marketing_Indirect_Channel_Portfolio_LDM_updated.ldm | B20: PASS | C20: INFO | D20: MODEL_QUALITY | E20: IDENTIFIER | F20: DISTRIBUTOR_SALES_REPRESENTATIVE_VISIT (DISTRIBUTOR_SLS_REPRESENTATIVE_VST) | H20: Entity has no primary identifier in either model | I20: (none) | J20: (none) | K20: Pre-existing in SAP PD, not caused by the migration. Define a primary identifier if the business requires unique referencing.
A21: 03_Lubes_Sales_Marketing_Indirect_Channel_Portfolio_LDM_updated.ldm | B21: PASS | C21: INFO | D21: MODEL_QUALITY | E21: IDENTIFIER | F21: DISTRIBUTOR_STOCK (DISTRIBUTOR_STCK) | H21: Entity has no primary identifier in either model | I21: (none) | J21: (none) | K21: Pre-existing in SAP PD, not caused by the migration. Define a primary identifier if the business requires unique referencing.
A22: 03_Lubes_Sales_Marketing_Indirect_Channel_Portfolio_LDM_updated.ldm | B22: PASS | C22: INFO | D22: MODEL_QUALITY | E22: IDENTIFIER | F22: PRODUCT_PRICE | H22: Entity has no primary identifier in either model | I22: (none) | J22: (none) | K22: Pre-existing in SAP PD, not caused by the migration. Define a primary identifier if the business requires unique referencing.
A23: 03_Lubes_Sales_Marketing_Indirect_Channel_Portfolio_LDM_updated.ldm | B23: PASS | C23: INFO | D23: MODEL_QUALITY | E23: IDENTIFIER | F23: PURCHASE_RETURN | H23: Entity has no primary identifier in either model | I23: (none) | J23: (none) | K23: Pre-existing in SAP PD, not caused by the migration. Define a primary identifier if the business requires unique referencing.
A24: 03_Lubes_Sales_Marketing_Indirect_Channel_Portfolio_LDM_updated.ldm | B24: PASS | C24: INFO | D24: MODEL_QUALITY | E24: IDENTIFIER | F24: RETAILER (RTLR) | H24: Entity has no primary identifier in either model | I24: (none) | J24: (none) | K24: Pre-existing in SAP PD, not caused by the migration. Define a primary identifier if the business requires unique referencing.
A25: 03_Lubes_Sales_Marketing_Indirect_Channel_Portfolio_LDM_updated.ldm | B25: PASS | C25: INFO | D25: MODEL_QUALITY | E25: IDENTIFIER | F25: SALES_RETURN (SLS_RTRN) | H25: Entity has no primary identifier in either model | I25: (none) | J25: (none) | K25: Pre-existing in SAP PD, not caused by the migration. Define a primary identifier if the business requires unique referencing.
A26: 03_Lubes_Sales_Marketing_Indirect_Channel_Portfolio_LDM_updated.ldm | B26: PASS | C26: INFO | D26: MODEL_QUALITY | E26: IDENTIFIER | F26: SHELL_COMPANY (SHLL_CMPNY) | H26: Entity has no primary identifier in either model | I26: (none) | J26: (none) | K26: Pre-existing in SAP PD, not caused by the migration. Define a primary identifier if the business requires unique referencing.
A27: 03_Lubes_Sales_Marketing_Indirect_Channel_Portfolio_LDM_updated.ldm | B27: PASS | C27: VERIFIED | D27: IDENTIFIER_VERIFIED | E27: IDENTIFIER | F27: ACCOUNTS_RECEIVABLE | G27: Identifier_1 | H27: Primary identifier migrated intact — 1 member(s) match in name and order | I27: Identifier_1 → RECEIPT_NUMBER | J27: Identifier_1 → RECEIPT_NUMBER | K27: No action required.
A28: 03_Lubes_Sales_Marketing_Indirect_Channel_Portfolio_LDM_updated.ldm | B28: PASS | C28: VERIFIED | D28: IDENTIFIER_VERIFIED | E28: IDENTIFIER | F28: CAMPAIGN_SOURCE | G28: Identifier_1 | H28: Primary identifier migrated intact — 2 member(s) match in name and order | I28: Identifier_1 → CAMPAIGN_SOURCE_ID, CAMPAIGN_ | J28: Identifier_1 → CAMPAIGN_SOURCE_ID, CAMPAIGN_ | K28: No action required.
A29: 03_Lubes_Sales_Marketing_Indirect_Channel_Portfolio_LDM_updated.ldm | B29: PASS | C29: VERIFIED | D29: IDENTIFIER_VERIFIED | E29: IDENTIFIER | F29: COUNTRY | G29: Identifier_1 | H29: Primary identifier migrated intact — 1 member(s) match in name and order | I29: Identifier_1 → COUNTRY_ID | J29: Identifier_1 → COUNTRY_ID | K29: No action required.
A30: 03_Lubes_Sales_Marketing_Indirect_Channel_Portfolio_LDM_updated.ldm | B30: PASS | C30: VERIFIED | D30: IDENTIFIER_VERIFIED | E30: IDENTIFIER | F30: CUSTOMER (CSTMR) | G30: Identifier_1 | H30: Primary identifier migrated intact — 1 member(s) match in name and order | I30: Identifier_1 → CSTMR_MSTR_ID | J30: Identifier_1 → CSTMR_MSTR_ID | K30: No action required.
A31: 03_Lubes_Sales_Marketing_Indirect_Channel_Portfolio_LDM_updated.ldm | B31: PASS | C31: VERIFIED | D31: IDENTIFIER_VERIFIED | E31: IDENTIFIER | F31: CUSTOMER_GROUP (CSTMR_GRP) | G31: Identifier_1 | H31: Primary identifier migrated intact — 1 member(s) match in name and order | I31: Identifier_1 → CSTMR_GRP_ID | J31: Identifier_1 → CSTMR_GRP_ID | K31: No action required.
A32: 03_Lubes_Sales_Marketing_Indirect_Channel_Portfolio_LDM_updated.ldm | B32: PASS | C32: VERIFIED | D32: IDENTIFIER_VERIFIED | E32: IDENTIFIER | F32: DISTRIBUTOR | G32: Identifier_1 | H32: Primary identifier migrated intact — 1 member(s) match in name and order | I32: Identifier_1 → DISTRIBUTOR_ID | J32: Identifier_1 → DISTRIBUTOR_ID | K32: No action required.
A33: 03_Lubes_Sales_Marketing_Indirect_Channel_Portfolio_LDM_updated.ldm | B33: PASS | C33: VERIFIED | D33: IDENTIFIER_VERIFIED | E33: IDENTIFIER | F33: DISTRIBUTOR_SALES_MANAGER (DISTRIBUTOR_SLS_MNGR) | G33: Identifier_1 | H33: Primary identifier migrated intact — 2 member(s) match in name and order | I33: Identifier_1 → DISTRIBUTOR_ID, DSM_ID | J33: Identifier_1 → DISTRIBUTOR_ID, DSM_ID | K33: No action required.
A34: 03_Lubes_Sales_Marketing_Indirect_Channel_Portfolio_LDM_updated.ldm | B34: PASS | C34: VERIFIED | D34: IDENTIFIER_VERIFIED | E34: IDENTIFIER | F34: DISTRIBUTOR_SALES_REPRESENTATIVE (DISTRIBUTOR_SLS_REPRESENTATIVE) | G34: Identifier_1 | H34: Primary identifier migrated intact — 1 member(s) match in name and order | I34: Identifier_1 → DSR_ID | J34: Identifier_1 → DSR_ID | K34: No action required.
A35: 03_Lubes_Sales_Marketing_Indirect_Channel_Portfolio_LDM_updated.ldm | B35: PASS | C35: VERIFIED | D35: IDENTIFIER_VERIFIED | E35: IDENTIFIER | F35: INVOICE (INVOICE_HEADER) | G35: Identifier_1 | H35: Primary identifier migrated intact — 1 member(s) match in name and order | I35: Identifier_1 → INVOICE_NUMBER | J35: Identifier_1 → INVOICE_NUMBER | K35: No action required.
A36: 03_Lubes_Sales_Marketing_Indirect_Channel_Portfolio_LDM_updated.ldm | B36: PASS | C36: VERIFIED | D36: IDENTIFIER_VERIFIED | E36: IDENTIFIER | F36: LEAD | G36: Identifier_1 | H36: Primary identifier migrated intact — 1 member(s) match in name and order | I36: Identifier_1 → LEAD_ID | J36: Identifier_1 → LEAD_ID | K36: No action required.
A37: 03_Lubes_Sales_Marketing_Indirect_Channel_Portfolio_LDM_updated.ldm | B37: PASS | C37: VERIFIED | D37: IDENTIFIER_VERIFIED | E37: IDENTIFIER | F37: LEAD_CAMPAIGN | G37: Identifier_1 | H37: Primary identifier migrated intact — 1 member(s) match in name and order | I37: Identifier_1 → LEAD_CAMPAIGN_ID | J37: Identifier_1 → LEAD_CAMPAIGN_ID | K37: No action required.
A38: 03_Lubes_Sales_Marketing_Indirect_Channel_Portfolio_LDM_updated.ldm | B38: PASS | C38: VERIFIED | D38: IDENTIFIER_VERIFIED | E38: IDENTIFIER | F38: OUTLET | G38: Identifier_1 | H38: Primary identifier migrated intact — 1 member(s) match in name and order | I38: Identifier_1 → OUTLET_ID | J38: Identifier_1 → OUTLET_ID | K38: No action required.
... A46: 03_Lubes_Sales_Marketing_Indirect_Channel_Portfolio_LDM_updated.ldm | B46: PASS | C46: VERIFIED | D46: IDENTIFIER_VERIFIED | E46: IDENTIFIER | F46: SURVEY (SRVY) | G46: Identifier_1 | H46: Primary identifier migrated intact — 1 member(s) match in name and order | I46: Identifier_1 → SRVY_ID | J46: Identifier_1 → SRVY_ID | K46: No action required.

Sheet ENTITY_MATRIX
A1: Model | B1: Status | C1: Match Basis | D1: SAP PD Entity Name | E1: SAP PD Code | F1: erwin Entity Name | G1: erwin Code | H1: Attrs (SAP PD) | I1: Attrs (erwin) | J1: Attrs Matched | K1: SAP PD Primary Identifier | L1: erwin Primary Identifier | M1: CRITICAL | N1: WARNING | O1: INFO
A2: 03_Lubes_Sales_Marketing_Indirect_Channel_Portfolio_LDM_updated.ldm | B2: MATCHED | C2: code | D2: INVOICE | E2: INVOICE_HEADER | F2: INVOICE | G2: INVOICE_HEADER | H2: 15 | I2: 15 | J2: 15 | K2: Identifier_1 → INVOICE_NUMBER | L2: Identifier_1 → INVOICE_NUMBER | M2: 0 | N2: 0 | O2: 0
A3: 03_Lubes_Sales_Marketing_Indirect_Channel_Portfolio_LDM_updated.ldm | B3: MATCHED | C3: code | D3: DISCOUNT | E3: DISCOUNT | F3: DISCOUNT | G3: DISCOUNT | H3: 9 | I3: 9 | J3: 9 | K3: (none) | L3: (none) | M3: 0 | N3: 0 | O3: 1
A4: 03_Lubes_Sales_Marketing_Indirect_Channel_Portfolio_LDM_updated.ldm | B4: MATCHED | C4: code | D4: ACCOUNTS_RECEIVABLE | E4: ACCOUNTS_RECEIVABLE | F4: ACCOUNTS_RECEIVABLE | G4: ACCOUNTS_RECEIVABLE | H4: 7 | I4: 7 | J4: 7 | K4: Identifier_1 → RECEIPT_NUMBER | L4: Identifier_1 → RECEIPT_NUMBER | M4: 0 | N4: 0 | O4: 0
A5: 03_Lubes_Sales_Marketing_Indirect_Channel_Portfolio_LDM_updated.ldm | B5: MATCHED | C5: code | D5: DISTRIBUTOR_ANNUAL_TARGET | E5: DISTRIBUTOR_ANNL_TRGT | F5: DISTRIBUTOR_ANNUAL_TARGET | G5: DISTRIBUTOR_ANNL_TRGT | H5: 4 | I5: 4 | J5: 4 | K5: (none) | L5: (none) | M5: 0 | N5: 0 | O5: 1
A6: 03_Lubes_Sales_Marketing_Indirect_Channel_Portfolio_LDM_updated.ldm | B6: MATCHED | C6: code | D6: DISTRIBUTOR_SALES_REPRESENTATIVE_VISIT | E6: DISTRIBUTOR_SLS_REPRESENTATIVE_VST | F6: DISTRIBUTOR_SALES_REPRESENTATIVE_VISIT | G6: DISTRIBUTOR_SLS_REPRESENTATIVE_VST | H6: 3 | I6: 3 | J6: 3 | K6: (none) | L6: (none) | M6: 0 | N6: 0 | O6: 1
A7: 03_Lubes_Sales_Marketing_Indirect_Channel_Portfolio_LDM_updated.ldm | B7: MATCHED | C7: code | D7: DISTRIBUTOR_SALES_REPRESENTATIVE | E7: DISTRIBUTOR_SLS_REPRESENTATIVE | F7: DISTRIBUTOR_SALES_REPRESENTATIVE | G7: DISTRIBUTOR_SLS_REPRESENTATIVE | H7: 3 | I7: 3 | J7: 3 | K7: Identifier_1 → DSR_ID | L7: Identifier_1 → DSR_ID | M7: 0 | N7: 0 | O7: 0
A8: 03_Lubes_Sales_Marketing_Indirect_Channel_Portfolio_LDM_updated.ldm | B8: MATCHED | C8: code | D8: DISTRIBUTOR_SALES_MANAGER | E8: DISTRIBUTOR_SLS_MNGR | F8: DISTRIBUTOR_SALES_MANAGER | G8: DISTRIBUTOR_SLS_MNGR | H8: 2 | I8: 2 | J8: 2 | K8: Identifier_1 → DISTRIBUTOR_ID, DSM_ID | L8: Identifier_1 → DISTRIBUTOR_ID, DSM_ID | M8: 0 | N8: 0 | O8: 0
A9: 03_Lubes_Sales_Marketing_Indirect_Channel_Portfolio_LDM_updated.ldm | B9: MATCHED | C9: code | D9: OUTLET | E9: OUTLET | F9: OUTLET | G9: OUTLET | H9: 18 | I9: 18 | J9: 18 | K9: Identifier_1 → OUTLET_ID | L9: Identifier_1 → OUTLET_ID | M9: 0 | N9: 0 | O9: 0
A10: 03_Lubes_Sales_Marketing_Indirect_Channel_Portfolio_LDM_updated.ldm | B10: MATCHED | C10: code | D10: LEAD_CAMPAIGN | E10: LEAD_CAMPAIGN | F10: LEAD_CAMPAIGN | G10: LEAD_CAMPAIGN | H10: 3 | I10: 6 | J10: 3 | K10: Identifier_1 → LEAD_CAMPAIGN_ID | L10: Identifier_1 → LEAD_CAMPAIGN_ID | M10: 0 | N10: 0 | O10: 3
A11: 03_Lubes_Sales_Marketing_Indirect_Channel_Portfolio_LDM_updated.ldm | B11: MATCHED | C11: code | D11: LEAD | E11: LEAD | F11: LEAD | G11: LEAD | H11: 9 | I11: 9 | J11: 9 | K11: Identifier_1 → LEAD_ID | L11: Identifier_1 → LEAD_ID | M11: 0 | N11: 0 | O11: 0
A12: 03_Lubes_Sales_Marketing_Indirect_Channel_Portfolio_LDM_updated.ldm | B12: MATCHED | C12: code | D12: COUNTRY | E12: COUNTRY | F12: COUNTRY | G12: COUNTRY | H12: 5 | I12: 6 | J12: 5 | K12: Identifier_1 → COUNTRY_ID | L12: Identifier_1 → COUNTRY_ID | M12: 0 | N12: 0 | O12: 1
A13: 03_Lubes_Sales_Marketing_Indirect_Channel_Portfolio_LDM_updated.ldm | B13: MATCHED | C13: code | D13: CAMPAIGN_SOURCE | E13: CAMPAIGN_SOURCE | F13: CAMPAIGN_SOURCE | G13: CAMPAIGN_SOURCE | H13: 2 | I13: 2 | J13: 2 | K13: Identifier_1 → CAMPAIGN_SOURCE_ID, CAMPAIGN_ | L13: Identifier_1 → CAMPAIGN_SOURCE_ID, CAMPAIGN_ | M13: 0 | N13: 0 | O13: 0
... A31: 03_Lubes_Sales_Marketing_Indirect_Channel_Portfolio_LDM_updated.ldm | B31: MATCHED | C31: code | D31: PRODUCT_FAMILY | E31: PRODUCT_FAMILY | F31: PRODUCT_FAMILY | G31: PRODUCT_FAMILY | H31: 2 | I31: 2 | J31: 2 | K31: Identifier_1 → PRODUCT_FAMILY_ID | L31: Identifier_1 → PRODUCT_FAMILY_ID | M31: 0 | N31: 0 | O31: 0

Sheet RELATIONSHIPS
A1: Model | B1: Status | C1: Match Basis | D1: Entities | E1: SAP PD Relationship | F1: erwin Relationship | G1: SAP PD Degree | H1: erwin Degree | I1: SAP PD Semantics | J1: erwin Semantics
A2: 03_Lubes_Sales_Marketing_Indirect_Channel_Portfolio_LDM_updated.ldm | B2: MATCHED | C2: name | D2: SELL_IN_SLS_ORDR ↔ DISTRIBUTOR_SLS_REPRESENTATIVE | E2: requests | F2: requests | G2: 1:N | H2: 1:N | I2: SELL_IN_SLS_ORDR (0,n) relates to → (0,1) relates to DISTRIBUTOR_SLS_REPRESENTATIVE [1:N] | J2: DISTRIBUTOR_SLS_REPRESENTATIVE (0,1) relates to → (0,n) relates to SELL_IN_SLS_ORDR [N:1]
A3: 03_Lubes_Sales_Marketing_Indirect_Channel_Portfolio_LDM_updated.ldm | B3: MATCHED | C3: name | D3: PRDCT ↔ SHLL_CMPNY | E3: sells | F3: sells | G3: 1:N | H3: 1:N | I3: PRDCT (0,n) relates to → (0,1) relates to SHLL_CMPNY [1:N] | J3: SHLL_CMPNY (0,1) relates to → (0,n) relates to PRDCT [N:1]
A4: 03_Lubes_Sales_Marketing_Indirect_Channel_Portfolio_LDM_updated.ldm | B4: MATCHED | C4: name | D4: SELL_IN_SLS_ORDR ↔ SHLL_CMPNY | E4: generates sell in for distributors | F4: generates sell in for distributors | G4: 1:N | H4: 1:N | I4: SELL_IN_SLS_ORDR (0,n) relates to → (0,1) relates to SHLL_CMPNY [1:N] | J4: SHLL_CMPNY (0,1) relates to → (0,n) relates to SELL_IN_SLS_ORDR [N:1]
A5: 03_Lubes_Sales_Marketing_Indirect_Channel_Portfolio_LDM_updated.ldm | B5: MATCHED | C5: name | D5: SLS_AR ↔ SHLL_CMPNY | E5: sell through sales organization in a | F5: sell through sales organization in a | G5: 1:N | H5: 1:N | I5: SLS_AR (0,n) relates to → (0,1) relates to SHLL_CMPNY [1:N] | J5: SHLL_CMPNY (0,1) relates to → (0,n) relates to SLS_AR [N:1]
A6: 03_Lubes_Sales_Marketing_Indirect_Channel_Portfolio_LDM_updated.ldm | B6: MATCHED | C6: name | D6: DISTRIBUTOR ↔ SHLL_CMPNY | E6: sales product to | F6: sales product to | G6: 1:N | H6: 1:N | I6: DISTRIBUTOR (0,n) relates to → (0,1) relates to SHLL_CMPNY [1:N] | J6: SHLL_CMPNY (0,1) relates to → (0,n) relates to DISTRIBUTOR [N:1]
A7: 03_Lubes_Sales_Marketing_Indirect_Channel_Portfolio_LDM_updated.ldm | B7: MATCHED | C7: name | D7: COUNTRY ↔ DISTRIBUTOR | E7: assigned to a | F7: assigned to a | G7: 1:1 | H7: 1:1 | I7: COUNTRY (0,1) relates to → (0,1) relates to DISTRIBUTOR [1:1] | J7: DISTRIBUTOR (0,1) relates to → (0,1) relates to COUNTRY [1:1]
A8: 03_Lubes_Sales_Marketing_Indirect_Channel_Portfolio_LDM_updated.ldm | B8: MATCHED | C8: name | D8: LEAD ↔ DISTRIBUTOR | E8: gets | F8: gets | G8: 1:N | H8: 1:N | I8: LEAD (0,n) relates to → (1,1) relates to DISTRIBUTOR [1:N] | J8: DISTRIBUTOR (1,1) relates to → (0,n) relates to LEAD [N:1]
A9: 03_Lubes_Sales_Marketing_Indirect_Channel_Portfolio_LDM_updated.ldm | B9: MATCHED | C9: name | D9: DISTRIBUTOR_SLS_MNGR ↔ DISTRIBUTOR | E9: assigns | F9: assigns | G9: 1:N | H9: 1:N | I9: DISTRIBUTOR_SLS_MNGR (0,n) relates to → (1,1) relates to DISTRIBUTOR [1:N] | J9: DISTRIBUTOR (1,1) relates to → (0,n) relates to DISTRIBUTOR_SLS_MNGR [N:1]
A10: 03_Lubes_Sales_Marketing_Indirect_Channel_Portfolio_LDM_updated.ldm | B10: MATCHED | C10: name | D10: SLS_RTRN ↔ DISTRIBUTOR | E10: accepts | F10: accepts | G10: 1:N | H10: 1:N | I10: SLS_RTRN (0,n) relates to → (0,1) relates to DISTRIBUTOR [1:N] | J10: DISTRIBUTOR (0,1) relates to → (0,n) relates to SLS_RTRN [N:1]
A11: 03_Lubes_Sales_Marketing_Indirect_Channel_Portfolio_LDM_updated.ldm | B11: MATCHED | C11: name | D11: DISTRIBUTOR_STCK ↔ DISTRIBUTOR | E11: manages | F11: manages | G11: 1:N | H11: 1:N | I11: DISTRIBUTOR_STCK (0,n) relates to → (0,1) relates to DISTRIBUTOR [1:N] | J11: DISTRIBUTOR (0,1) relates to → (0,n) relates to DISTRIBUTOR_STCK [N:1]
A12: 03_Lubes_Sales_Marketing_Indirect_Channel_Portfolio_LDM_updated.ldm | B12: MATCHED | C12: name | D12: PRDCT ↔ DISTRIBUTOR | E12: buys | F12: buys | G12: 1:N | H12: 1:N | I12: PRDCT (0,n) relates to → (0,1) relates to DISTRIBUTOR [1:N] | J12: DISTRIBUTOR (0,1) relates to → (0,n) relates to PRDCT [N:1]
... A43: 03_Lubes_Sales_Marketing_Indirect_Channel_Portfolio_LDM_updated.ldm | B43: MATCHED | C43: endpoints+cardinality | D43: DISTRIBUTOR_SLS_REPRESENTATIVE_VST ↔ DISTRIBUTOR_SLS_REPRESENTATIVE | E43: visit details are stored in | F43: visit details are stored in | G43: 1:N | H43: 1:N | I43: DISTRIBUTOR_SLS_REPRESENTATIVE_VST (0,n) relates to → (0,1) relates to DISTRIBUTOR_SLS_REPRESENTATIVE [1:N] | J43: DISTRIBUTOR_SLS_REPRESENTATIVE (0,1) relates to → (0,n) relates to DISTRIBUTOR_SLS_REPRESENTATIVE_VST [N:1]

Sheet CATEGORY_ANALYSIS
A1: Category | B1: CRITICAL | C1: WARNING | D1: INFO | E1: VERIFIED | F1: Total | G1: Models Affected
A2: IDENTIFIER_VERIFIED | B2: 0 | C2: 0 | D2: 0 | E2: 20 | F2: 20 | G2: 1
A3: MODEL_QUALITY | B3: 0 | C3: 1 | D3: 10 | E3: 0 | F3: 11 | G3: 1
A4: DATA_TYPE | B4: 0 | C4: 9 | D4: 0 | E4: 0 | F4: 9 | G4: 1
A5: FALLBACK_MATCH | B5: 0 | C5: 0 | D5: 5 | E5: 0 | F5: 5 | G5: 1

Sheet DESCRIPTION
A1: Mapping | B1: MATCHED | C1: MISMATCH | D1: MISSING IN ERWIN | E1: MISSING IN SAP PD | F1: BOTH EMPTY | G1: Total
A2: Annotation → Extended Notes | B2: 0 | C2: 0 | D2: 0 | E2: 0 | F2: 212 | G2: 212
A3: Comment → Note | B3: 22 | C3: 0 | D3: 0 | E3: 0 | F3: 190 | G3: 212
A4: Description → Definition | B4: 0 | C4: 0 | D4: 0 | E4: 0 | F4: 212 | G4: 212
A6: Model | B6: Object Type | C6: Object | D6: Code | E6: Mapping | F6: Source Field | G6: Target Field | H6: SAP PD Value (source) | I6: erwin Value (target) | J6: Status | K6: Similarity %
A7: 03_Lubes_Indirect_Sales_Marketing_Portfolio_LDM | B7: ENTITY | C7: ACCOUNTS_RECEIVABLE | D7: ACCOUNTS_RECEIVABLE | E7: Comment → Note | F7: SAP PD Comment | G7: erwin Note | H7: Accounts receivable (AR) is an accounting term for money owed to a business for goods or services that it has delivered but not been paid for yet. | I7: Accounts receivable (AR) is an accounting term for money owed to a business for goods or services that it has delivered but not been paid for yet. | J7: MATCHED
A8: 03_Lubes_Indirect_Sales_Marketing_Portfolio_LDM | B8: ENTITY | C8: COUNTRY | D8: COUNTRY | E8: Comment → Note | F8: SAP PD Comment | G8: erwin Note | H8: A geographical area or a nation occupying a particular territory. | I8: A geographical area or a nation occupying a particular territory. | J8: MATCHED
A9: 03_Lubes_Indirect_Sales_Marketing_Portfolio_LDM | B9: ENTITY | C9: CUSTOMER | D9: CSTMR | E9: Comment → Note | F9: SAP PD Comment | G9: erwin Note | H9: The role of the Party that takes title to purchased goods or services purchased from Shell. It includes prospect customers too. In Shell context a B2B Customer is reserved for business organizations or persons, including retail stores, but excluding end consumers (e.g.people buying petrol/gasoline to put in their vehicle) that purchase a product for their own use in the pursuit of its business. Customers may use the products for a variety of reasons (e.g. manufacturing, transport, heating, etc)… | I9: The role of the Party that takes title to purchased goods or services purchased from Shell. It includes prospect customers too. In Shell context a B2B Customer is reserved for business organizations or persons, including retail stores, but excluding end consumers (e.g.people buying petrol/gasoline to put in their vehicle) that purchase a product for their own use in the pursuit of its business. Customers may use the products for a variety of reasons (e.g. manufacturing, transport, heating, etc)… | J9: MATCHED
A10: 03_Lubes_Indirect_Sales_Marketing_Portfolio_LDM | B10: ENTITY | C10: CUSTOMER_GROUP | D10: CSTMR_GRP | E10: Comment → Note | F10: SAP PD Comment | G10: erwin Note | H10: Customer group is a key that classifies what type of customer we are dealing with-Direct, Indirect, Retail etc. | I10: Customer group is a key that classifies what type of customer we are dealing with-Direct, Indirect, Retail etc. | J10: MATCHED
A11: 03_Lubes_Indirect_Sales_Marketing_Portfolio_LDM | B11: ENTITY | C11: DISCOUNT | D11: DISCOUNT | E11: Comment → Note | F11: SAP PD Comment | G11: erwin Note | H11: Discount provided to customer order based on Promotions | I11: Discount provided to customer order based on Promotions | J11: MATCHED
A12: 03_Lubes_Indirect_Sales_Marketing_Portfolio_LDM | B12: ENTITY | C12: DISTRIBUTOR | D12: DISTRIBUTOR | E12: Comment → Note | F12: SAP PD Comment | G12: erwin Note | H12: A Shell Customer, that sells and distributes Shell-branded products on Shell's behalf. Distributors have Sales Targets. | I12: A Shell Customer, that sells and distributes Shell-branded products on Shell's behalf. Distributors have Sales Targets. | J12: MATCHED
A13: 03_Lubes_Indirect_Sales_Marketing_Portfolio_LDM | B13: ENTITY | C13: DISTRIBUTOR_ANNUAL_TARGET | D13: DISTRIBUTOR_ANNL_TRGT | E13: Comment → Note | F13: SAP PD Comment | G13: erwin Note | H13: The minimum quantity (target) of Product that is set for a Distributor Sales Rep to sell in a given period (e.g. monthly) | I13: The minimum quantity (target) of Product that is set for a Distributor Sales Rep to sell in a given period (e.g. monthly) | J13: MATCHED
A14: 03_Lubes_Indirect_Sales_Marketing_Portfolio_LDM | B14: ENTITY | C14: DISTRIBUTOR_SALES_MANAGER | D14: DISTRIBUTOR_SLS_MNGR | E14: Comment → Note | F14: SAP PD Comment | G14: erwin Note | H14: Distributor's employee details like supervisor's of sales representatives. | I14: Distributor's employee details like supervisor's of sales representatives. | J14: MATCHED
A15: 03_Lubes_Indirect_Sales_Marketing_Portfolio_LDM | B15: ENTITY | C15: DISTRIBUTOR_SALES_REPRESENTATIVE | D15: DISTRIBUTOR_SLS_REPRESENTATIVE | E15: Comment → Note | F15: SAP PD Comment | G15: erwin Note | H15: Distributors assigns sales representative for their respective region to sell, promote products, generate leads and complete survey and manage relationships with the end customers.Distributor's employee details like supervisor, Sales Representative etc. | I15: Distributors assigns sales representative for their respective region to sell, promote products, generate leads and complete survey and manage relationships with the end customers.Distributor's employee details like supervisor, Sales Representative etc. | J15: MATCHED
A16: 03_Lubes_Indirect_Sales_Marketing_Portfolio_LDM | B16: ENTITY | C16: DISTRIBUTOR_SALES_REPRESENTATIVE_VISIT | D16: DISTRIBUTOR_SLS_REPRESENTATIVE_VST | E16: Comment → Note | F16: SAP PD Comment | G16: erwin Note | H16: When distributor's sales representative attend visit to their end customer or to prospects then visit data is stored at distributor's end. | I16: When distributor's sales representative attend visit to their end customer or to prospects then visit data is stored at distributor's end. | J16: MATCHED
A17: 03_Lubes_Indirect_Sales_Marketing_Portfolio_LDM | B17: ENTITY | C17: INVOICE | D17: INVOICE_HEADER | E17: Comment → Note | F17: SAP PD Comment | G17: erwin Note | H17: Details of Invoice are maintained here. | I17: Details of Invoice are maintained here. | J17: MATCHED
A18: 03_Lubes_Indirect_Sales_Marketing_Portfolio_LDM | B18: ENTITY | C18: OUTLET | D18: OUTLET | E18: Comment → Note | F18: SAP PD Comment | G18: erwin Note | H18: Customer is used to maintain outlet details | I18: Customer is used to maintain outlet details | J18: MATCHED
... A28: 03_Lubes_Indirect_Sales_Marketing_Portfolio_LDM | B28: ENTITY | C28: SURVEY | D28: SRVY | E28: Comment → Note | F28: SAP PD Comment | G28: erwin Note | H28: Surveys pertaining to distributor satisfaction | I28: Surveys pertaining to distributor satisfaction | J28: MATCHED
A29: 03_Lubes_Indirect_Sales_Marketing_Portfolio_LDM | B29: ATTRIBUTE | C29: ACCOUNTS_RECEIVABLE.Due_Date | D29: DUE_DATE | E29: Annotation → Extended Notes | F29: SAP PD Annotation | G29: erwin Extended Notes | J29: BOTH_EMPTY
A30: 03_Lubes_Indirect_Sales_Marketing_Portfolio_LDM | B30: ATTRIBUTE | C30: ACCOUNTS_RECEIVABLE.Due_Date | D30: DUE_DATE | E30: Comment → Note | F30: SAP PD Comment | G30: erwin Note | J30: BOTH_EMPTY
A31: 03_Lubes_Indirect_Sales_Marketing_Portfolio_LDM | B31: ATTRIBUTE | C31: ACCOUNTS_RECEIVABLE.Due_Date | D31: DUE_DATE | E31: Description → Definition | F31: SAP PD Description | G31: erwin Definition | J31: BOTH_EMPTY
A32: 03_Lubes_Indirect_Sales_Marketing_Portfolio_LDM | B32: ATTRIBUTE | C32: ACCOUNTS_RECEIVABLE.Invoice_Amount | D32: INVOICE_AMOUNT | E32: Annotation → Extended Notes | F32: SAP PD Annotation | G32: erwin Extended Notes | J32: BOTH_EMPTY
A33: 03_Lubes_Indirect_Sales_Marketing_Portfolio_LDM | B33: ATTRIBUTE | C33: ACCOUNTS_RECEIVABLE.Invoice_Amount | D33: INVOICE_AMOUNT | E33: Comment → Note | F33: SAP PD Comment | G33: erwin Note | J33: BOTH_EMPTY
A34: 03_Lubes_Indirect_Sales_Marketing_Portfolio_LDM | B34: ATTRIBUTE | C34: ACCOUNTS_RECEIVABLE.Invoice_Amount | D34: INVOICE_AMOUNT | E34: Description → Definition | F34: SAP PD Description | G34: erwin Definition | J34: BOTH_EMPTY
A35: 03_Lubes_Indirect_Sales_Marketing_Portfolio_LDM | B35: ATTRIBUTE | C35: ACCOUNTS_RECEIVABLE.Invoice_Date | D35: INVOICE_DATE | E35: Annotation → Extended Notes | F35: SAP PD Annotation | G35: erwin Extended Notes | J35: BOTH_EMPTY
A36: 03_Lubes_Indirect_Sales_Marketing_Portfolio_LDM | B36: ATTRIBUTE | C36: ACCOUNTS_RECEIVABLE.Invoice_Date | D36: INVOICE_DATE | E36: Comment → Note | F36: SAP PD Comment | G36: erwin Note | J36: BOTH_EMPTY
A37: 03_Lubes_Indirect_Sales_Marketing_Portfolio_LDM | B37: ATTRIBUTE | C37: ACCOUNTS_RECEIVABLE.Invoice_Date | D37: INVOICE_DATE | E37: Description → Definition | F37: SAP PD Description | G37: erwin Definition | J37: BOTH_EMPTY
A38: 03_Lubes_Indirect_Sales_Marketing_Portfolio_LDM | B38: ATTRIBUTE | C38: ACCOUNTS_RECEIVABLE.Invoice_Number | D38: INVOICE_NUMBER | E38: Annotation → Extended Notes | F38: SAP PD Annotation | G38: erwin Extended Notes | J38: BOTH_EMPTY
A39: 03_Lubes_Indirect_Sales_Marketing_Portfolio_LDM | B39: ATTRIBUTE | C39: ACCOUNTS_RECEIVABLE.Invoice_Number | D39: INVOICE_NUMBER | E39: Comment → Note | F39: SAP PD Comment | G39: erwin Note | J39: BOTH_EMPTY
A40: 03_Lubes_Indirect_Sales_Marketing_Portfolio_LDM | B40: ATTRIBUTE | C40: ACCOUNTS_RECEIVABLE.Invoice_Number | D40: INVOICE_NUMBER | E40: Description → Definition | F40: SAP PD Description | G40: erwin Definition | J40: BOTH_EMPTY
... A642: 03_Lubes_Indirect_Sales_Marketing_Portfolio_LDM | B642: ENTITY | C642: SURVEY | D642: SRVY | E642: Description → Definition | F642: SAP PD Description | G642: erwin Definition | J642: BOTH_EMPTY

Sheet CONFIG
A1: Setting | B1: Value
A2: ATTRIBUTE_MATCH_KEY | B2: auto
A3: CASE_INSENSITIVE | B3: True
A4: CHECKPOINT_EVERY | B4: 100
A5: CHECK_ALTERNATE_IDENTIFIERS | B5: True
A6: CHECK_ASSOCIATIONS | B6: True
A7: CHECK_ATTRIBUTES | B7: True
A8: CHECK_ATTRIBUTE_ORDER | B8: False
A9: CHECK_BUSINESS_NAMES | B9: True
A10: CHECK_BUSINESS_RULES | B10: True
A11: CHECK_CARDINALITY | B11: True
A12: CHECK_DATA_TYPES | B12: True
... A34: ERWIN_MIGRATED_KEY_HANDLING | B34: relationship
A35: ERWIN_MODELS_DIR
A36: ERWIN_NULL_OPTION_CODES | B36: {"101": false, "100": true}
A37: ERWIN_RELATIONSHIP_TYPE_CODES | B37: {"2": "IDENTIFYING", "7": "NON_IDENTIFYING", "4": "MANY_TO_MANY", "9": "SUBTYPE"}
A38: ERWIN_SUBTYPE_AS_INHERITANCE | B38: True
A39: EXCLUDE_ATTRIBUTE_PATTERNS | B39: []
A40: EXCLUDE_ENTITY_PATTERNS | B40: []
A41: EXPORT_FINDINGS_CSV | B41: False
A42: EXPORT_JSON_SUMMARY | B42: False
A43: FIDELITY_MAX_PENALTY_PER_OBJECT | B43: 1.0
A44: FIDELITY_REVIEW_THRESHOLD | B44: 95.0
A45: FIDELITY_STAGE_WEIGHTS | B45: {"structural": 0.5, "documentation": 0.25, "udp": 0.25}
A46: FIDELITY_WEIGHTS | B46: {"CRITICAL": 1.0, "WARNING": 0.35, "INFO": 0.05}
A47: FLAG_DEFINITION_LOSS | B47: True
A48: MAPPING_CSV
A49: MATCH_STRATEGY | B49: filename
A50: MAX_DIFF_ROWS_PER_MODEL | B50: 500
A51: MAX_MODELS_FOR_DETAIL_SHEETS | B51: 200
A52: MAX_WORKERS | B52: 8
A53: NORMALIZE_PLURALS | B53: True
A54: OUTPUT_DIR
A55: PD_EXTENSIONS | B55: [".ldm", ".xml"]
A56: PD_MODELS_DIR
A57: PD_TO_ERWIN_APPROVED_TYPES | B57: {"CHAR": "{'CHAR'}", "VARCHAR": "{'VARCHAR'}", "TEXT": "{'LONGTEXT', 'CLOB', 'TEXT', 'LONG_TEXT'}", "INTEGER": "{'INTEGER'}", "SMALLINT": "{'SMALLINT'}", "BIGINT": "{'BIGINT'}", "DECIMAL": "{'DECIMAL'}", "DATE": "{'DATE'}", "TIME": "{'TIME'}", "TIMESTAMP": "{'TIMESTAMP'}", "BINARY": "{'BINARY'}", "VARBINARY": "{'VARBINARY'}", "BOOLEAN": "{'BIT', 'BOOL', 'BOOLEAN'}", "XML": "{'XML'}"}
A58: PREFIX_LENGTH | B58: 8
A59: REPORT_FALLBACK_MATCHES | B59: True
A60: REPORT_FILENAME | B60: ldm_validation_report.xlsx
A61: REPORT_FONT | B61: Calibri
...

Sheet 03_Lubes_Sales_Marketing_Ind
A1: 03_Lubes_Sales_Marketing_Indirect_Channel_Portfolio_LDM_updated.ldm vs 03_Lubes_Sales_Marketing_Indirect_Channel_Portfolio_LDM_updated.xml | PASS | fidelity 98.97% | 30/30 entities matched | 42/42 relationships matched | 0 critical / 10 warning / 15 info
A2: # | B2: Severity | C2: Category | D2: Object Type | E2: Object | F2: Member | G2: Message | H2: SAP PD Value | I2: erwin Value | J2: Recommended Action
A3: 1 | B3: WARNING | C3: DATA_TYPE | D3: ATTRIBUTE | E3: CUSTOMER (CSTMR) | F3: CSTMR_MSTR_ID | G3: Logical data type differs (compared at approved PD→erwin type matrix) | H3: VARCHAR / TEXT | I3: CHAR(18) / TEXT | J3: Reassign the erwin logical datatype or domain so both sides express the same logical type family.
A4: 2 | B4: WARNING | C4: DATA_TYPE | D4: ATTRIBUTE | E4: CUSTOMER (CSTMR) | F4: CSTMR_NM | G4: Logical data type differs (compared at approved PD→erwin type matrix) | H4: VARCHAR(2) / TEXT | I4: CHAR(18) / TEXT | J4: Reassign the erwin logical datatype or domain so both sides express the same logical type family.
A5: 3 | B5: WARNING | C5: DATA_TYPE | D5: ATTRIBUTE | E5: DISTRIBUTOR | F5: CRRNT_STTS | G5: Logical data type differs (compared at approved PD→erwin type matrix) | H5: nvarchar(10) → VARCHAR(10) / TEXT | I5: CHAR(18) / TEXT | J5: Reassign the erwin logical datatype or domain so both sides express the same logical type family.
A6: 4 | B6: WARNING | C6: DATA_TYPE | D6: ATTRIBUTE | E6: DISTRIBUTOR | F6: DISTRIBUTOR_CD | G6: Logical data type differs (compared at approved PD→erwin type matrix) | H6: nvarchar(10) → VARCHAR(10) / TEXT | I6: CHAR(18) / TEXT | J6: Reassign the erwin logical datatype or domain so both sides express the same logical type family.
A7: 5 | B7: WARNING | C7: DATA_TYPE | D7: ATTRIBUTE | E7: DISTRIBUTOR | F7: DISTRIBUTOR_NM | G7: Logical data type differs (compared at approved PD→erwin type matrix) | H7: nvarchar(100) → VARCHAR(100) / TEXT | I7: CHAR(18) / TEXT | J7: Reassign the erwin logical datatype or domain so both sides express the same logical type family.
A8: 6 | B8: WARNING | C8: DATA_TYPE | D8: ATTRIBUTE | E8: SALES_AREA (SLS_AR) | F8: CSTMR_MSTR_ID | G8: Logical data type differs (compared at approved PD→erwin type matrix) | H8: VARCHAR / TEXT | I8: CHAR(18) / TEXT | J8: Reassign the erwin logical datatype or domain so both sides express the same logical type family.
A9: 7 | B9: WARNING | C9: DATA_TYPE | D9: ATTRIBUTE | E9: SALES_AREA (SLS_AR) | F9: DSTRBTN_CHNNL | G9: Logical data type differs (compared at approved PD→erwin type matrix) | H9: VARCHAR / TEXT | I9: CHAR(18) / TEXT | J9: Reassign the erwin logical datatype or domain so both sides express the same logical type family.
A10: 8 | B10: WARNING | C10: DATA_TYPE | D10: ATTRIBUTE | E10: SALES_AREA (SLS_AR) | F10: SLS_ORGNZTN_ID | G10: Logical data type differs (compared at 'family' strictness) | H10: VARCHAR> / OTHER | I10: CHAR(18) / TEXT | J10: Reassign the erwin logical datatype or domain so both sides express the same logical type family.
A11: 9 | B11: WARNING | C11: DATA_TYPE | D11: ATTRIBUTE | E11: SELL_IN_SALES_ORDER (SELL_IN_SLS_ORDR) | F11: DT | G11: Logical data type differs (compared at 'family' strictness) | H11: DATETIME / TEMPORAL | I11: CHAR(18) / TEXT | J11: Reassign the erwin logical datatype or domain so both sides express the same logical type family.
A12: 10 | B12: WARNING | C12: MODEL_QUALITY | D12: ENTITY | E12: RETAILER (RTLR) | G12: Entity participates in no relationship or hierarchy in erwin — possible orphan from the migration | I12: 0 relationships | J12: Reconnect the entity, or confirm it is genuinely standalone reference data.
A13: 11 | B13: INFO | C13: FALLBACK_MATCH | D13: ATTRIBUTE | E13: COUNTRY | F13: DISTRIBUTOR_ID | G13: erwin role-migrated key attribute — reconciled by the corresponding SAP PD relationship, which expresses the same foreign key without a separate attribute object | H13: — | I13: DISTRIBUTOR_ID | J13: No action required; informational only.
A14: 12 | B14: INFO | C14: FALLBACK_MATCH | D14: ATTRIBUTE | E14: DISTRIBUTOR | F14: CSTMR_MSTR_ID | G14: erwin role-migrated key attribute — reconciled by the corresponding SAP PD relationship, which expresses the same foreign key without a separate attribute object | H14: — | I14: CSTMR_MSTR_ID | J14: No action required; informational only.
A15: 13 | B15: INFO | C15: FALLBACK_MATCH | D15: ATTRIBUTE | E15: LEAD_CAMPAIGN | F15: CAMPAIGN_ | G15: erwin role-migrated key attribute — reconciled by the corresponding SAP PD relationship, which expresses the same foreign key without a separate attribute object | H15: — | I15: CAMPAIGN_ | J15: No action required; informational only.
A16: 14 | B16: INFO | C16: FALLBACK_MATCH | D16: ATTRIBUTE | E16: LEAD_CAMPAIGN | F16: CAMPAIGN_SOURCE_ID | G16: erwin role-migrated key attribute — reconciled by the corresponding SAP PD relationship, which expresses the same foreign key without a separate attribute object | H16: — | I16: CAMPAIGN_SOURCE_ID | J16: No action required; informational only.
A17: 15 | B17: INFO | C17: FALLBACK_MATCH | D17: ATTRIBUTE | E17: LEAD_CAMPAIGN | F17: LEAD_ID | G17: erwin role-migrated key attribute — reconciled by the corresponding SAP PD relationship, which expresses the same foreign key without a separate attribute object | H17: — | I17: LEAD_ID | J17: No action required; informational only.
A18: 16 | B18: INFO | C18: MODEL_QUALITY | D18: IDENTIFIER | E18: DISCOUNT | G18: Entity has no primary identifier in either model | H18: (none) | I18: (none) | J18: Pre-existing in SAP PD, not caused by the migration. Define a primary identifier if the business requires unique referencing.
A19: 17 | B19: INFO | C19: MODEL_QUALITY | D19: IDENTIFIER | E19: DISTRIBUTOR_ANNUAL_TARGET (DISTRIBUTOR_ANNL_TRGT) | G19: Entity has no primary identifier in either model | H19: (none) | I19: (none) | J19: Pre-existing in SAP PD, not caused by the migration. Define a primary identifier if the business requires unique referencing.
A20: 18 | B20: INFO | C20: MODEL_QUALITY | D20: IDENTIFIER | E20: DISTRIBUTOR_LEARNING (DISTRIBUTOR_LRNNG) | G20: Entity has no primary identifier in either model | H20: (none) | I20: (none) | J20: Pre-existing in SAP PD, not caused by the migration. Define a primary identifier if the business requires unique referencing.
A21: 19 | B21: INFO | C21: MODEL_QUALITY | D21: IDENTIFIER | E21: DISTRIBUTOR_SALES_REPRESENTATIVE_VISIT (DISTRIBUTOR_SLS_REPRESENTATIVE_VST) | G21: Entity has no primary identifier in either model | H21: (none) | I21: (none) | J21: Pre-existing in SAP PD, not caused by the migration. Define a primary identifier if the business requires unique referencing.
A22: 20 | B22: INFO | C22: MODEL_QUALITY | D22: IDENTIFIER | E22: DISTRIBUTOR_STOCK (DISTRIBUTOR_STCK) | G22: Entity has no primary identifier in either model | H22: (none) | I22: (none) | J22: Pre-existing in SAP PD, not caused by the migration. Define a primary identifier if the business requires unique referencing.
A23: 21 | B23: INFO | C23: MODEL_QUALITY | D23: IDENTIFIER | E23: PRODUCT_PRICE | G23: Entity has no primary identifier in either model | H23: (none) | I23: (none) | J23: Pre-existing in SAP PD, not caused by the migration. Define a primary identifier if the business requires unique referencing.
A24: 22 | B24: INFO | C24: MODEL_QUALITY | D24: IDENTIFIER | E24: PURCHASE_RETURN | G24: Entity has no primary identifier in either model | H24: (none) | I24: (none) | J24: Pre-existing in SAP PD, not caused by the migration. Define a primary identifier if the business requires unique referencing.
A25: 23 | B25: INFO | C25: MODEL_QUALITY | D25: IDENTIFIER | E25: RETAILER (RTLR) | G25: Entity has no primary identifier in either model | H25: (none) | I25: (none) | J25: Pre-existing in SAP PD, not caused by the migration. Define a primary identifier if the business requires unique referencing.
A26: 24 | B26: INFO | C26: MODEL_QUALITY | D26: IDENTIFIER | E26: SALES_RETURN (SLS_RTRN) | G26: Entity has no primary identifier in either model | H26: (none) | I26: (none) | J26: Pre-existing in SAP PD, not caused by the migration. Define a primary identifier if the business requires unique referencing.
A27: 25 | B27: INFO | C27: MODEL_QUALITY | D27: IDENTIFIER | E27: SHELL_COMPANY (SHLL_CMPNY) | G27: Entity has no primary identifier in either model | H27: (none) | I27: (none) | J27: Pre-existing in SAP PD, not caused by the migration. Define a primary identifier if the business requires unique referencing.
A28: 26 | B28: VERIFIED | C28: IDENTIFIER_VERIFIED | D28: IDENTIFIER | E28: ACCOUNTS_RECEIVABLE | F28: Identifier_1 | G28: Primary identifier migrated intact — 1 member(s) match in name and order | H28: Identifier_1 → RECEIPT_NUMBER | I28: Identifier_1 → RECEIPT_NUMBER | J28: No action required.
A29: 27 | B29: VERIFIED | C29: IDENTIFIER_VERIFIED | D29: IDENTIFIER | E29: CAMPAIGN_SOURCE | F29: Identifier_1 | G29: Primary identifier migrated intact — 2 member(s) match in name and order | H29: Identifier_1 → CAMPAIGN_SOURCE_ID, CAMPAIGN_ | I29: Identifier_1 → CAMPAIGN_SOURCE_ID, CAMPAIGN_ | J29: No action required.
A30: 28 | B30: VERIFIED | C30: IDENTIFIER_VERIFIED | D30: IDENTIFIER | E30: COUNTRY | F30: Identifier_1 | G30: Primary identifier migrated intact — 1 member(s) match in name and order | H30: Identifier_1 → COUNTRY_ID | I30: Identifier_1 → COUNTRY_ID | J30: No action required.
A31: 29 | B31: VERIFIED | C31: IDENTIFIER_VERIFIED | D31: IDENTIFIER | E31: CUSTOMER (CSTMR) | F31: Identifier_1 | G31: Primary identifier migrated intact — 1 member(s) match in name and order | H31: Identifier_1 → CSTMR_MSTR_ID | I31: Identifier_1 → CSTMR_MSTR_ID | J31: No action required.
A32: 30 | B32: VERIFIED | C32: IDENTIFIER_VERIFIED | D32: IDENTIFIER | E32: CUSTOMER_GROUP (CSTMR_GRP) | F32: Identifier_1 | G32: Primary identifier migrated intact — 1 member(s) match in name and order | H32: Identifier_1 → CSTMR_GRP_ID | I32: Identifier_1 → CSTMR_GRP_ID | J32: No action required.
A33: 31 | B33: VERIFIED | C33: IDENTIFIER_VERIFIED | D33: IDENTIFIER | E33: DISTRIBUTOR | F33: Identifier_1 | G33: Primary identifier migrated intact — 1 member(s) match in name and order | H33: Identifier_1 → DISTRIBUTOR_ID | I33: Identifier_1 → DISTRIBUTOR_ID | J33: No action required.
A34: 32 | B34: VERIFIED | C34: IDENTIFIER_VERIFIED | D34: IDENTIFIER | E34: DISTRIBUTOR_SALES_MANAGER (DISTRIBUTOR_SLS_MNGR) | F34: Identifier_1 | G34: Primary identifier migrated intact — 2 member(s) match in name and order | H34: Identifier_1 → DISTRIBUTOR_ID, DSM_ID | I34: Identifier_1 → DISTRIBUTOR_ID, DSM_ID | J34: No action required.
A35: 33 | B35: VERIFIED | C35: IDENTIFIER_VERIFIED | D35: IDENTIFIER | E35: DISTRIBUTOR_SALES_REPRESENTATIVE (DISTRIBUTOR_SLS_REPRESENTATIVE) | F35: Identifier_1 | G35: Primary identifier migrated intact — 1 member(s) match in name and order | H35: Identifier_1 → DSR_ID | I35: Identifier_1 → DSR_ID | J35: No action required.
A36: 34 | B36: VERIFIED | C36: IDENTIFIER_VERIFIED | D36: IDENTIFIER | E36: INVOICE (INVOICE_HEADER) | F36: Identifier_1 | G36: Primary identifier migrated intact — 1 member(s) match in name and order | H36: Identifier_1 → INVOICE_NUMBER | I36: Identifier_1 → INVOICE_NUMBER | J36: No action required.
A37: 35 | B37: VERIFIED | C37: IDENTIFIER_VERIFIED | D37: IDENTIFIER | E37: LEAD | F37: Identifier_1 | G37: Primary identifier migrated intact — 1 member(s) match in name and order | H37: Identifier_1 → LEAD_ID | I37: Identifier_1 → LEAD_ID | J37: No action required.
A38: 36 | B38: VERIFIED | C38: IDENTIFIER_VERIFIED | D38: IDENTIFIER | E38: LEAD_CAMPAIGN | F38: Identifier_1 | G38: Primary identifier migrated intact — 1 member(s) match in name and order | H38: Identifier_1 → LEAD_CAMPAIGN_ID | I38: Identifier_1 → LEAD_CAMPAIGN_ID | J38: No action required.
A39: 37 | B39: VERIFIED | C39: IDENTIFIER_VERIFIED | D39: IDENTIFIER | E39: OUTLET | F39: Identifier_1 | G39: Primary identifier migrated intact — 1 member(s) match in name and order | H39: Identifier_1 → OUTLET_ID | I39: Identifier_1 → OUTLET_ID | J39: No action required.
... A47: 45 | B47: VERIFIED | C47: IDENTIFIER_VERIFIED | D47: IDENTIFIER | E47: SURVEY (SRVY) | F47: Identifier_1 | G47: Primary identifier migrated intact — 1 member(s) match in name and order | H47: Identifier_1 → SRVY_ID | I47: Identifier_1 → SRVY_ID | J47: No action required.

Sheet UDP_MAPPING_SUMMARY
A1: UDP Migration Report - SAP PowerDesigner to erwin Data Modeler
A3: Run Information
A4: Report generated | B4: 2026-09-05 21:16:23
A5: Model name | B5: 03_Lubes_Sales_Marketing_Indirect_Channel_Portfolio_LDM_updated
A6: Source SAP model | B6: C:\Users\SrinivasaPesala\Desktop\migration-platform_4_sept_final_h_l_m\sappdmodels\ldm\03_Lubes_Sales_Marketing_Indirect_Channel_Portfolio_LDM_updated.ldm | C6: PowerDesigner model read for this run.
A7: Target erwin model | B7: n/a | C7: File the UDPs were written into.
A8: PowerDesigner version | B8: 16.7.0.6372
A9: Repository extraction id | B9: 30512774 | C9: Proves which point-in-time extract this migration came from.
A10: Injection executed | B10: No - report built from source data only | C10: Values below are reported as Not Verified because no injection result file was available.
A11: erwin session | B11: Not recorded
A13: Source Model (SAP PowerDesigner)
A14: Complexity band | B14: B4 - High / Very High | C14: From sow_classify.py, per the SOW Complexity Classification Spectrum.
A15: SOW automation range | B15: 20% to 50%
A16: Entities in source model | B16: 30
A17: Attributes in source model | B17: 182
A18: Extension properties found | B18: 0
A19: Extension values found | B19: 0
A21: UDP Definitions
A22: UDP definitions requested | B22: =MAX(0,COUNTA(UDP_DEFINITIONS!$A:$A)-1) | C22: Each UDP is defined twice in erwin, once for the Entity owner and once for the Model owner.
A23: Created in erwin dictionary | B23: =COUNTIF(UDP_DEFINITIONS!$J:$J,"Created*") | C23: Counted per UDP, not per owner.
A24: Updated in erwin dictionary | B24: =COUNTIF(UDP_DEFINITIONS!$J:$J,"Updated*") | C24: UDPs that already existed in the target model and were re-pointed.
A25: Definition failures | B25: =COUNTIF(UDP_DEFINITIONS!$N:$N,"FAILED*") | C25: A UDP counts as failed if erwin rejected either owner definition. See the Exceptions sheet for the reason.
A27: Value Reconciliation
A28: Entities matched in erwin | B28: Not recorded | C28: Entities the injector found in the target .erwin model.
A29: Source values to migrate | B29: =MAX(0,COUNTA(UDP_VALUE_RECON!$C:$C)-1)
A30: Applied to erwin | B30: =COUNTIF(UDP_VALUE_RECON!$H:$H,"Applied*")
A31: Applied and verified (read back) | B31: =COUNTIF(UDP_VALUE_RECON!$I:$I,"Match") | C31: Value was written, then read back out of erwin and compared.
A32: Applied but value altered | B32: =COUNTIF(UDP_VALUE_RECON!$I:$I,"Mismatch")
A33: Not applied | B33: =COUNTIF(UDP_VALUE_RECON!$H:$H,"Skipped*")
A34: Blank source values | B34: =COUNTBLANK(UDP_VALUE_RECON!$E$2:$E$91) | C34: Properties present in PowerDesigner but holding no value.
A36: Result
A37: Application rate | B37: =IF(B29=0,0,B30/B29) | C37: Share of source values erwin accepted.
A38: Verification rate | B38: =IF(B29=0,0,B31/B29) | C38: Share of source values confirmed identical inside erwin.
A39: High severity exceptions | B39: =COUNTIF(UDP_EXCEPTIONS!$A:$A,"High") | C39: Listed on the Exceptions sheet.
A40: Migration verdict | B40: NOT VERIFIED - NO INJECTION RESULTS | C40: This report was built from source data alone. Re-run batch_run.py to produce a verified report.
A42: Counts on this sheet are live formulas over the other three sheets, so they stay correct if rows are filtered or corrected during review.

Sheet UDP_DEFINITIONS
A1: UDP Name | B1: Inferred Type | C1: Length | D1: Value List (Observed) | E1: Source Path | F1: Source Coverage | G1: Distinct Observed | H1: List Source | I1: erwin Owner Types | J1: erwin Dictionary Action | K1: Values Expected | L1: Values Applied | M1: Values Verified | N1: Definition Status
A2: PD_ObjectID | B2: Text | C2: 40 | I2: Entity, Model | J2: Not Recorded | K2: =COUNTIF(UDP_VALUE_RECON!$C:$C,$A2) | L2: =COUNTIFS(UDP_VALUE_RECON!$C:$C,$A2,UDP_VALUE_RECON!$H:$H,"Applied*") | M2: =COUNTIFS(UDP_VALUE_RECON!$C:$C,$A2,UDP_VALUE_RECON!$I:$I,"Match") | N2: Defined
A3: PD_SourceExtraction | B3: Text | C3: 20 | I3: Entity, Model | J3: Not Recorded | K3: =COUNTIF(UDP_VALUE_RECON!$C:$C,$A3) | L3: =COUNTIFS(UDP_VALUE_RECON!$C:$C,$A3,UDP_VALUE_RECON!$H:$H,"Applied*") | M3: =COUNTIFS(UDP_VALUE_RECON!$C:$C,$A3,UDP_VALUE_RECON!$I:$I,"Match") | N3: Defined
A4: PD_SourceModel | B4: Text | C4: 120 | I4: Entity, Model | J4: Not Recorded | K4: =COUNTIF(UDP_VALUE_RECON!$C:$C,$A4) | L4: =COUNTIFS(UDP_VALUE_RECON!$C:$C,$A4,UDP_VALUE_RECON!$H:$H,"Applied*") | M4: =COUNTIFS(UDP_VALUE_RECON!$C:$C,$A4,UDP_VALUE_RECON!$I:$I,"Match") | N4: Defined

Sheet UDP_VALUE_RECON
A1: Entity Name | B1: PD Object ID | C1: UDP | D1: Source Path | E1: Source Value (PowerDesigner) | F1: Target Value (erwin) | G1: Applied To | H1: Status | I1: Match | J1: Notes
A2: INVOICE | B2: 84EA5DD8-6A1A-45B8-8B2D-56057B619E63 | C2: PD_ObjectID | E2: 84EA5DD8-6A1A-45B8-8B2D-56057B619E63 | G2: Entity | H2: Not Verified - No Injection Result | I2: Not Applied | J2: No injection result recorded for this value.
A3: INVOICE | B3: 84EA5DD8-6A1A-45B8-8B2D-56057B619E63 | C3: PD_SourceExtraction | E3: 46603045 | G3: Entity | H3: Not Verified - No Injection Result | I3: Not Applied | J3: No injection result recorded for this value.
A4: INVOICE | B4: 84EA5DD8-6A1A-45B8-8B2D-56057B619E63 | C4: PD_SourceModel | E4: 03_Lubes_Sales_Marketing_Indirect_Channel_Portfolio_LDM_updated | G4: Entity | H4: Not Verified - No Injection Result | I4: Not Applied | J4: No injection result recorded for this value.
A5: DISCOUNT | B5: FD78AA7B-4711-4963-8DB9-ECB1B24D0E68 | C5: PD_ObjectID | E5: FD78AA7B-4711-4963-8DB9-ECB1B24D0E68 | G5: Entity | H5: Not Verified - No Injection Result | I5: Not Applied | J5: No injection result recorded for this value.
A6: DISCOUNT | B6: FD78AA7B-4711-4963-8DB9-ECB1B24D0E68 | C6: PD_SourceExtraction | E6: 46603045 | G6: Entity | H6: Not Verified - No Injection Result | I6: Not Applied | J6: No injection result recorded for this value.
