Workbook

Sheet Summary
A1: UDP Comparison - SAP PowerDesigner vs erwin - 05_Carbon_Calculator
A3: Run Information
A4: Report generated | B4: 2026-09-05 21:17:08
A5: Model | B5: 05_Carbon_Calculator
A6: Model type | B6: PDM
A7: Source SAP model | B7: C:\Users\SrinivasaPesala\Desktop\migration-platform_4_sept_final_h_l_m\sappdmodels\pdm\05_Carbon_Calculator.pdm
A8: erwin model compared | B8: erwinmodels\2_preprocessed\erwin\05_Carbon_Calculator.erwin
A9: erwin readback method | B9: com | C9: See the Diagnostics sheet.
A11: Comparison
A12: UDP values compared | B12: =MAX(0,COUNTA('UDP Comparison'!$C:$C)-1)
A13: PASS | B13: =COUNTIF('UDP Comparison'!$F$2:$F$1592,"PASS") | C13: erwin holds exactly the value PowerDesigner held.
A14: MISMATCH | B14: =COUNTIF('UDP Comparison'!$F$2:$F$1592,"MISMATCH") | C14: erwin holds a different value.
A15: MISSING | B15: =COUNTIF('UDP Comparison'!$F$2:$F$1592,"MISSING") | C15: PowerDesigner had a value; erwin holds nothing.
A16: BLANK IN SAP | B16: =COUNTIF('UDP Comparison'!$F$2:$F$1592,"BLANK IN SAP") | C16: Nothing to migrate, so erwin holding nothing is correct. Excluded from the pass rate.
A17: EXTRA IN ERWIN | B17: =COUNTIF('UDP Comparison'!$F$2:$F$1592,"EXTRA IN ERWIN") | C17: erwin holds a value with no matching source row.
A19: Result
A20: Comparable values | B20: =B13+B14+B15 | C20: PASS + MISMATCH + MISSING. Blank source values are not a migration outcome, so they are not counted here.
A21: Pass rate | B21: =IF(B20=0,0,B13/B20)
A22: Verdict | B22: =IF(B20=0,"NO SOURCE VALUES TO MIGRATE",IF(B13=B20,"PASS",IF(B13=0,"FAIL - NO VALUES MATCHED","REVIEW REQUIRED"))) | C22: PASS only when every migratable value matches erwin exactly.
A24: Counts are live formulas over the UDP Comparison sheet, bounded to the rows this run wrote.

Sheet UDP Comparison
A1: Entity Name | B1: Applied To | C1: UDP Name | D1: SAP Value | E1: erwin Value | F1: Status | G1: Source Path | H1: Note
A2: ACTIVITY_CATEGORY | B2: Entity | C2: PII | D2: false | F2: MISSING | G2: SHL_LDM_EntityPropertyExtension.PII | H2: erwin holds no value for this UDP on this object.
A3: ACTIVITY_CATEGORY_DIMENSION | B3: Entity | C3: PII | D3: false | F3: MISSING | G3: SHL_LDM_EntityPropertyExtension.PII | H3: erwin holds no value for this UDP on this object.
A4: ACTIVITY_CATEGORY_PARAMETER | B4: Entity | C4: PII | D4: false | F4: MISSING | G4: SHL_LDM_EntityPropertyExtension.PII | H4: erwin holds no value for this UDP on this object.
A5: ACTIVITY_CATEGORY_TYPE | B5: Entity | C5: PII | D5: false | F5: MISSING | G5: SHL_LDM_EntityPropertyExtension.PII | H5: erwin holds no value for this UDP on this object.
A6: ACTIVITY_CATEGORY_TYPE_DIMENSION | B6: Entity | C6: PII | D6: false | F6: MISSING | G6: SHL_LDM_EntityPropertyExtension.PII | H6: erwin holds no value for this UDP on this object.
A7: ACTIVITY_TYPE_PARAMETER | B7: Entity | C7: PII | D7: false | F7: MISSING | G7: SHL_LDM_EntityPropertyExtension.PII | H7: erwin holds no value for this UDP on this object.
A8: ACTIVITY_TYPE_PARAMETER_FACTOR | B8: Entity | C8: PII | D8: false | F8: MISSING | G8: SHL_LDM_EntityPropertyExtension.PII | H8: erwin holds no value for this UDP on this object.
A9: APPLICATION_EQUIPMENT | B9: Entity | C9: PII | D9: false | F9: MISSING | G9: SHL_LDM_EntityPropertyExtension.PII | H9: erwin holds no value for this UDP on this object.
A10: APPLICATION_METHOD | B10: Entity | C10: PII | D10: false | F10: MISSING | G10: SHL_LDM_EntityPropertyExtension.PII | H10: erwin holds no value for this UDP on this object.
A11: CLIENT | B11: Entity | C11: PII | D11: false | F11: MISSING | G11: SHL_LDM_EntityPropertyExtension.PII | H11: erwin holds no value for this UDP on this object.
A12: CLIENT_UOM | B12: Entity | C12: PII | D12: false | F12: MISSING | G12: SHL_LDM_EntityPropertyExtension.PII | H12: erwin holds no value for this UDP on this object.
A13: DIMENSION | B13: Entity | C13: PII | D13: false | F13: MISSING | G13: SHL_LDM_EntityPropertyExtension.PII | H13: erwin holds no value for this UDP on this object.
... A51: UOM_DERIVATION | B51: Entity | C51: PII | D51: false | F51: MISSING | G51: SHL_LDM_EntityPropertyExtension.PII | H51: erwin holds no value for this UDP on this object.
A52: ACTIVITY_CATEGORY | B52: Entity | C52: CSI | D52: false | E52: false | F52: PASS | G52: SHL_LDM_EntityPropertyExtension.CSI
A53: ACTIVITY_CATEGORY | B53: Entity | C53: CommerciallySensitiveInformation | D53: No Commercially Sensitive Information | E53: No Commercially Sensitive Information | F53: PASS | G53: BIM-core.CommerciallySensitiveInformation
A54: ACTIVITY_CATEGORY | B54: Entity | C54: Criticality | D54: No Critical Data | E54: No Critical Data | F54: PASS | G54: BIM-core.Criticality
A55: ACTIVITY_CATEGORY | B55: Entity | C55: DataArea | D55: Emission | E55: Emission | F55: PASS | G55: BIM-core.DataArea
A56: ACTIVITY_CATEGORY | B56: Entity | C56: DataCategory | D56: Structured | E56: Structured | F56: PASS | G56: BIM-core.DataCategory
A57: ACTIVITY_CATEGORY | B57: Entity | C57: DataConfidentiality | D57: Internal | E57: Internal | F57: PASS | G57: BIM-core.DataConfidentiality
A58: ACTIVITY_CATEGORY | B58: Entity | C58: DesignStatus | D58: Approved | E58: Approved | F58: PASS | G58: BIM-core.DesignStatus
A59: ACTIVITY_CATEGORY | B59: Entity | C59: EntityCategory | D59: Master | E59: Master | F59: PASS | G59: BIM-core.EntityCategory
A60: ACTIVITY_CATEGORY | B60: Entity | C60: EntityPersonalData | D60: No Personal Data | E60: No Personal Data | F60: PASS | G60: BIM-core.EntityPersonalData
A61: ACTIVITY_CATEGORY | B61: Entity | C61: FinancialPersonalData | D61: No Financial Personal Data | E61: No Financial Personal Data | F61: PASS | G61: BIM-core.FinancialPersonalData
A62: ACTIVITY_CATEGORY | B62: Entity | C62: MTED_Encryption_Required | D62: false | E62: false | F62: PASS | G62: SHL_LDM_EntityPropertyExtension.MTED_Encryption_Required
A63: ACTIVITY_CATEGORY | B63: Entity | C63: MappingLevel | D63: BLM | E63: BLM | F63: PASS | G63: BIM-core.MappingLevel
A64: ACTIVITY_CATEGORY | B64: Entity | C64: MapsToEntity | D64: EMISSION_ACTIVITY_CATEGORY | E64: EMISSION_ACTIVITY_CATEGORY | F64: PASS | G64: BIM-core.MapsToEntity
A65: ACTIVITY_CATEGORY | B65: Entity | C65: PD_ObjectID | D65: 0F32AF8D-C27C-4BA2-B673-8DEAD1AC55D3 | E65: 0F32AF8D-C27C-4BA2-B673-8DEAD1AC55D3 | F65: PASS
A66: ACTIVITY_CATEGORY | B66: Entity | C66: PD_SourceExtraction | D66: 46603045 | E66: 46603045 | F66: PASS
A67: ACTIVITY_CATEGORY | B67: Entity | C67: PD_SourceModel | D67: 05_Carbon_Calculator | E67: 05_Carbon_Calculator | F67: PASS
A68: ACTIVITY_CATEGORY | B68: Entity | C68: SensitivePersonalData | D68: No Sensitive Personal Data | E68: No Sensitive Personal Data | F68: PASS | G68: BIM-core.SensitivePersonalData
A69: ACTIVITY_CATEGORY_DIMENSION | B69: Entity | C69: CSI | D69: false | E69: false | F69: PASS | G69: SHL_LDM_EntityPropertyExtension.CSI
A70: ACTIVITY_CATEGORY_DIMENSION | B70: Entity | C70: CommerciallySensitiveInformation | D70: No Commercially Sensitive Information | E70: No Commercially Sensitive Information | F70: PASS | G70: BIM-core.CommerciallySensitiveInformation
A71: ACTIVITY_CATEGORY_DIMENSION | B71: Entity | C71: Criticality | D71: No Critical Data | E71: No Critical Data | F71: PASS | G71: BIM-core.Criticality
A72: ACTIVITY_CATEGORY_DIMENSION | B72: Entity | C72: DataArea | D72: Emission | E72: Emission | F72: PASS | G72: BIM-core.DataArea
A73: ACTIVITY_CATEGORY_DIMENSION | B73: Entity | C73: DataCategory | D73: Structured | E73: Structured | F73: PASS | G73: BIM-core.DataCategory
A74: ACTIVITY_CATEGORY_DIMENSION | B74: Entity | C74: DataConfidentiality | D74: Internal | E74: Internal | F74: PASS | G74: BIM-core.DataConfidentiality
A75: ACTIVITY_CATEGORY_DIMENSION | B75: Entity | C75: DesignStatus | D75: Approved | E75: Approved | F75: PASS | G75: BIM-core.DesignStatus
A76: ACTIVITY_CATEGORY_DIMENSION | B76: Entity | C76: EntityCategory | D76: Master | E76: Master | F76: PASS | G76: BIM-core.EntityCategory
A77: ACTIVITY_CATEGORY_DIMENSION | B77: Entity | C77: EntityPersonalData | D77: No Personal Data | E77: No Personal Data | F77: PASS | G77: BIM-core.EntityPersonalData
...

Sheet By UDP
A1: UDP Name | B1: Rows | C1: PASS | D1: MISMATCH | E1: MISSING | F1: BLANK IN SAP | G1: EXTRA IN ERWIN | H1: Pass Rate | I1: Verdict
A2: CSI | B2: =COUNTIF('UDP Comparison'!$C$2:$C$1592,$A2) | C2: =COUNTIFS('UDP Comparison'!$C$2:$C$1592,$A2,'UDP Comparison'!$F$2:$F$1592,"PASS") | D2: =COUNTIFS('UDP Comparison'!$C$2:$C$1592,$A2,'UDP Comparison'!$F$2:$F$1592,"MISMATCH") | E2: =COUNTIFS('UDP Comparison'!$C$2:$C$1592,$A2,'UDP Comparison'!$F$2:$F$1592,"MISSING") | F2: =COUNTIFS('UDP Comparison'!$C$2:$C$1592,$A2,'UDP Comparison'!$F$2:$F$1592,"BLANK IN SAP") | G2: =COUNTIFS('UDP Comparison'!$C$2:$C$1592,$A2,'UDP Comparison'!$F$2:$F$1592,"EXTRA IN ERWIN") | H2: =IF(($C2+$D2+$E2)=0,0,$C2/($C2+$D2+$E2)) | I2: =IF(($C2+$D2+$E2)=0,"Nothing to migrate",IF($C2=($C2+$D2+$E2),"PASS",IF($C2=0,"FAIL - none matched","REVIEW REQUIRED")))
A3: CommerciallySensitiveInformation | B3: =COUNTIF('UDP Comparison'!$C$2:$C$1592,$A3) | C3: =COUNTIFS('UDP Comparison'!$C$2:$C$1592,$A3,'UDP Comparison'!$F$2:$F$1592,"PASS") | D3: =COUNTIFS('UDP Comparison'!$C$2:$C$1592,$A3,'UDP Comparison'!$F$2:$F$1592,"MISMATCH") | E3: =COUNTIFS('UDP Comparison'!$C$2:$C$1592,$A3,'UDP Comparison'!$F$2:$F$1592,"MISSING") | F3: =COUNTIFS('UDP Comparison'!$C$2:$C$1592,$A3,'UDP Comparison'!$F$2:$F$1592,"BLANK IN SAP") | G3: =COUNTIFS('UDP Comparison'!$C$2:$C$1592,$A3,'UDP Comparison'!$F$2:$F$1592,"EXTRA IN ERWIN") | H3: =IF(($C3+$D3+$E3)=0,0,$C3/($C3+$D3+$E3)) | I3: =IF(($C3+$D3+$E3)=0,"Nothing to migrate",IF($C3=($C3+$D3+$E3),"PASS",IF($C3=0,"FAIL - none matched","REVIEW REQUIRED")))
A4: Criticality | B4: =COUNTIF('UDP Comparison'!$C$2:$C$1592,$A4) | C4: =COUNTIFS('UDP Comparison'!$C$2:$C$1592,$A4,'UDP Comparison'!$F$2:$F$1592,"PASS") | D4: =COUNTIFS('UDP Comparison'!$C$2:$C$1592,$A4,'UDP Comparison'!$F$2:$F$1592,"MISMATCH") | E4: =COUNTIFS('UDP Comparison'!$C$2:$C$1592,$A4,'UDP Comparison'!$F$2:$F$1592,"MISSING") | F4: =COUNTIFS('UDP Comparison'!$C$2:$C$1592,$A4,'UDP Comparison'!$F$2:$F$1592,"BLANK IN SAP") | G4: =COUNTIFS('UDP Comparison'!$C$2:$C$1592,$A4,'UDP Comparison'!$F$2:$F$1592,"EXTRA IN ERWIN") | H4: =IF(($C4+$D4+$E4)=0,0,$C4/($C4+$D4+$E4)) | I4: =IF(($C4+$D4+$E4)=0,"Nothing to migrate",IF($C4=($C4+$D4+$E4),"PASS",IF($C4=0,"FAIL - none matched","REVIEW REQUIRED")))
A5: DataArea | B5: =COUNTIF('UDP Comparison'!$C$2:$C$1592,$A5) | C5: =COUNTIFS('UDP Comparison'!$C$2:$C$1592,$A5,'UDP Comparison'!$F$2:$F$1592,"PASS") | D5: =COUNTIFS('UDP Comparison'!$C$2:$C$1592,$A5,'UDP Comparison'!$F$2:$F$1592,"MISMATCH") | E5: =COUNTIFS('UDP Comparison'!$C$2:$C$1592,$A5,'UDP Comparison'!$F$2:$F$1592,"MISSING") | F5: =COUNTIFS('UDP Comparison'!$C$2:$C$1592,$A5,'UDP Comparison'!$F$2:$F$1592,"BLANK IN SAP") | G5: =COUNTIFS('UDP Comparison'!$C$2:$C$1592,$A5,'UDP Comparison'!$F$2:$F$1592,"EXTRA IN ERWIN") | H5: =IF(($C5+$D5+$E5)=0,0,$C5/($C5+$D5+$E5)) | I5: =IF(($C5+$D5+$E5)=0,"Nothing to migrate",IF($C5=($C5+$D5+$E5),"PASS",IF($C5=0,"FAIL - none matched","REVIEW REQUIRED")))
A6: DataCategory | B6: =COUNTIF('UDP Comparison'!$C$2:$C$1592,$A6) | C6: =COUNTIFS('UDP Comparison'!$C$2:$C$1592,$A6,'UDP Comparison'!$F$2:$F$1592,"PASS") | D6: =COUNTIFS('UDP Comparison'!$C$2:$C$1592,$A6,'UDP Comparison'!$F$2:$F$1592,"MISMATCH") | E6: =COUNTIFS('UDP Comparison'!$C$2:$C$1592,$A6,'UDP Comparison'!$F$2:$F$1592,"MISSING") | F6: =COUNTIFS('UDP Comparison'!$C$2:$C$1592,$A6,'UDP Comparison'!$F$2:$F$1592,"BLANK IN SAP") | G6: =COUNTIFS('UDP Comparison'!$C$2:$C$1592,$A6,'UDP Comparison'!$F$2:$F$1592,"EXTRA IN ERWIN") | H6: =IF(($C6+$D6+$E6)=0,0,$C6/($C6+$D6+$E6)) | I6: =IF(($C6+$D6+$E6)=0,"Nothing to migrate",IF($C6=($C6+$D6+$E6),"PASS",IF($C6=0,"FAIL - none matched","REVIEW REQUIRED")))
A7: DataConfidentiality | B7: =COUNTIF('UDP Comparison'!$C$2:$C$1592,$A7) | C7: =COUNTIFS('UDP Comparison'!$C$2:$C$1592,$A7,'UDP Comparison'!$F$2:$F$1592,"PASS") | D7: =COUNTIFS('UDP Comparison'!$C$2:$C$1592,$A7,'UDP Comparison'!$F$2:$F$1592,"MISMATCH") | E7: =COUNTIFS('UDP Comparison'!$C$2:$C$1592,$A7,'UDP Comparison'!$F$2:$F$1592,"MISSING") | F7: =COUNTIFS('UDP Comparison'!$C$2:$C$1592,$A7,'UDP Comparison'!$F$2:$F$1592,"BLANK IN SAP") | G7: =COUNTIFS('UDP Comparison'!$C$2:$C$1592,$A7,'UDP Comparison'!$F$2:$F$1592,"EXTRA IN ERWIN") | H7: =IF(($C7+$D7+$E7)=0,0,$C7/($C7+$D7+$E7)) | I7: =IF(($C7+$D7+$E7)=0,"Nothing to migrate",IF($C7=($C7+$D7+$E7),"PASS",IF($C7=0,"FAIL - none matched","REVIEW REQUIRED")))
A8: DesignStatus | B8: =COUNTIF('UDP Comparison'!$C$2:$C$1592,$A8) | C8: =COUNTIFS('UDP Comparison'!$C$2:$C$1592,$A8,'UDP Comparison'!$F$2:$F$1592,"PASS") | D8: =COUNTIFS('UDP Comparison'!$C$2:$C$1592,$A8,'UDP Comparison'!$F$2:$F$1592,"MISMATCH") | E8: =COUNTIFS('UDP Comparison'!$C$2:$C$1592,$A8,'UDP Comparison'!$F$2:$F$1592,"MISSING") | F8: =COUNTIFS('UDP Comparison'!$C$2:$C$1592,$A8,'UDP Comparison'!$F$2:$F$1592,"BLANK IN SAP") | G8: =COUNTIFS('UDP Comparison'!$C$2:$C$1592,$A8,'UDP Comparison'!$F$2:$F$1592,"EXTRA IN ERWIN") | H8: =IF(($C8+$D8+$E8)=0,0,$C8/($C8+$D8+$E8)) | I8: =IF(($C8+$D8+$E8)=0,"Nothing to migrate",IF($C8=($C8+$D8+$E8),"PASS",IF($C8=0,"FAIL - none matched","REVIEW REQUIRED")))
A9: EntityCategory | B9: =COUNTIF('UDP Comparison'!$C$2:$C$1592,$A9) | C9: =COUNTIFS('UDP Comparison'!$C$2:$C$1592,$A9,'UDP Comparison'!$F$2:$F$1592,"PASS") | D9: =COUNTIFS('UDP Comparison'!$C$2:$C$1592,$A9,'UDP Comparison'!$F$2:$F$1592,"MISMATCH") | E9: =COUNTIFS('UDP Comparison'!$C$2:$C$1592,$A9,'UDP Comparison'!$F$2:$F$1592,"MISSING") | F9: =COUNTIFS('UDP Comparison'!$C$2:$C$1592,$A9,'UDP Comparison'!$F$2:$F$1592,"BLANK IN SAP") | G9: =COUNTIFS('UDP Comparison'!$C$2:$C$1592,$A9,'UDP Comparison'!$F$2:$F$1592,"EXTRA IN ERWIN") | H9: =IF(($C9+$D9+$E9)=0,0,$C9/($C9+$D9+$E9)) | I9: =IF(($C9+$D9+$E9)=0,"Nothing to migrate",IF($C9=($C9+$D9+$E9),"PASS",IF($C9=0,"FAIL - none matched","REVIEW REQUIRED")))
A10: EntityPersonalData | B10: =COUNTIF('UDP Comparison'!$C$2:$C$1592,$A10) | C10: =COUNTIFS('UDP Comparison'!$C$2:$C$1592,$A10,'UDP Comparison'!$F$2:$F$1592,"PASS") | D10: =COUNTIFS('UDP Comparison'!$C$2:$C$1592,$A10,'UDP Comparison'!$F$2:$F$1592,"MISMATCH") | E10: =COUNTIFS('UDP Comparison'!$C$2:$C$1592,$A10,'UDP Comparison'!$F$2:$F$1592,"MISSING") | F10: =COUNTIFS('UDP Comparison'!$C$2:$C$1592,$A10,'UDP Comparison'!$F$2:$F$1592,"BLANK IN SAP") | G10: =COUNTIFS('UDP Comparison'!$C$2:$C$1592,$A10,'UDP Comparison'!$F$2:$F$1592,"EXTRA IN ERWIN") | H10: =IF(($C10+$D10+$E10)=0,0,$C10/($C10+$D10+$E10)) | I10: =IF(($C10+$D10+$E10)=0,"Nothing to migrate",IF($C10=($C10+$D10+$E10),"PASS",IF($C10=0,"FAIL - none matched","REVIEW REQUIRED")))
A11: FinancialPersonalData | B11: =COUNTIF('UDP Comparison'!$C$2:$C$1592,$A11) | C11: =COUNTIFS('UDP Comparison'!$C$2:$C$1592,$A11,'UDP Comparison'!$F$2:$F$1592,"PASS") | D11: =COUNTIFS('UDP Comparison'!$C$2:$C$1592,$A11,'UDP Comparison'!$F$2:$F$1592,"MISMATCH") | E11: =COUNTIFS('UDP Comparison'!$C$2:$C$1592,$A11,'UDP Comparison'!$F$2:$F$1592,"MISSING") | F11: =COUNTIFS('UDP Comparison'!$C$2:$C$1592,$A11,'UDP Comparison'!$F$2:$F$1592,"BLANK IN SAP") | G11: =COUNTIFS('UDP Comparison'!$C$2:$C$1592,$A11,'UDP Comparison'!$F$2:$F$1592,"EXTRA IN ERWIN") | H11: =IF(($C11+$D11+$E11)=0,0,$C11/($C11+$D11+$E11)) | I11: =IF(($C11+$D11+$E11)=0,"Nothing to migrate",IF($C11=($C11+$D11+$E11),"PASS",IF($C11=0,"FAIL - none matched","REVIEW REQUIRED")))
A12: MTED_EDaM_Design_Status | B12: =COUNTIF('UDP Comparison'!$C$2:$C$1592,$A12) | C12: =COUNTIFS('UDP Comparison'!$C$2:$C$1592,$A12,'UDP Comparison'!$F$2:$F$1592,"PASS") | D12: =COUNTIFS('UDP Comparison'!$C$2:$C$1592,$A12,'UDP Comparison'!$F$2:$F$1592,"MISMATCH") | E12: =COUNTIFS('UDP Comparison'!$C$2:$C$1592,$A12,'UDP Comparison'!$F$2:$F$1592,"MISSING") | F12: =COUNTIFS('UDP Comparison'!$C$2:$C$1592,$A12,'UDP Comparison'!$F$2:$F$1592,"BLANK IN SAP") | G12: =COUNTIFS('UDP Comparison'!$C$2:$C$1592,$A12,'UDP Comparison'!$F$2:$F$1592,"EXTRA IN ERWIN") | H12: =IF(($C12+$D12+$E12)=0,0,$C12/($C12+$D12+$E12)) | I12: =IF(($C12+$D12+$E12)=0,"Nothing to migrate",IF($C12=($C12+$D12+$E12),"PASS",IF($C12=0,"FAIL - none matched","REVIEW REQUIRED")))
A13: MTED_EDaM_Entity_Critical_Data | B13: =COUNTIF('UDP Comparison'!$C$2:$C$1592,$A13) | C13: =COUNTIFS('UDP Comparison'!$C$2:$C$1592,$A13,'UDP Comparison'!$F$2:$F$1592,"PASS") | D13: =COUNTIFS('UDP Comparison'!$C$2:$C$1592,$A13,'UDP Comparison'!$F$2:$F$1592,"MISMATCH") | E13: =COUNTIFS('UDP Comparison'!$C$2:$C$1592,$A13,'UDP Comparison'!$F$2:$F$1592,"MISSING") | F13: =COUNTIFS('UDP Comparison'!$C$2:$C$1592,$A13,'UDP Comparison'!$F$2:$F$1592,"BLANK IN SAP") | G13: =COUNTIFS('UDP Comparison'!$C$2:$C$1592,$A13,'UDP Comparison'!$F$2:$F$1592,"EXTRA IN ERWIN") | H13: =IF(($C13+$D13+$E13)=0,0,$C13/($C13+$D13+$E13)) | I13: =IF(($C13+$D13+$E13)=0,"Nothing to migrate",IF($C13=($C13+$D13+$E13),"PASS",IF($C13=0,"FAIL - none matched","REVIEW REQUIRED")))
... A25: SensitivePersonalData | B25: =COUNTIF('UDP Comparison'!$C$2:$C$1592,$A25) | C25: =COUNTIFS('UDP Comparison'!$C$2:$C$1592,$A25,'UDP Comparison'!$F$2:$F$1592,"PASS") | D25: =COUNTIFS('UDP Comparison'!$C$2:$C$1592,$A25,'UDP Comparison'!$F$2:$F$1592,"MISMATCH") | E25: =COUNTIFS('UDP Comparison'!$C$2:$C$1592,$A25,'UDP Comparison'!$F$2:$F$1592,"MISSING") | F25: =COUNTIFS('UDP Comparison'!$C$2:$C$1592,$A25,'UDP Comparison'!$F$2:$F$1592,"BLANK IN SAP") | G25: =COUNTIFS('UDP Comparison'!$C$2:$C$1592,$A25,'UDP Comparison'!$F$2:$F$1592,"EXTRA IN ERWIN") | H25: =IF(($C25+$D25+$E25)=0,0,$C25/($C25+$D25+$E25)) | I25: =IF(($C25+$D25+$E25)=0,"Nothing to migrate",IF($C25=($C25+$D25+$E25),"PASS",IF($C25=0,"FAIL - none matched","REVIEW REQUIRED")))

Sheet Diagnostics
A1: Diagnostics - how erwin was read, and whether to trust it
A2: erwin model read | B2: erwinmodels\2_preprocessed\erwin\05_Carbon_Calculator.erwin
A3: Readback method | B3: com | C3: 'com' asks erwin directly and is authoritative. 'binary' decodes the .erwin file offline - independent of the API that wrote the data, but reverse-engineered, so it is a cross-check.
A4: Readback trustworthy | B4: Yes | C4: When No, the comparison is not reported as mismatches - the reading itself is in doubt.
A5: Objects read from erwin | B5: 101
A6: UDP values read from erwin | B6: 1531
A8: Readback notes
A9: - | B9: Read 1531 UDP value(s) from erwin via SCAPI.
A11: Source data warnings
A12: - | B12: None.
